Workbook
Name RevenueAge01: '18_Календарь_тарифы'!$B$24:$U$24
Name MinimumAge01: '18_Календарь_тарифы'!$B$54:$U$54
Name CapacityAge01: '18_Календарь_тарифы'!$W$24
Name MeanMinAge01: '18_Календарь_тарифы'!$X$24
Name RevenueAge02: '18_Календарь_тарифы'!$B$25:$U$25
Name MinimumAge02: '18_Календарь_тарифы'!$B$55:$U$55
Name CapacityAge02: '18_Календарь_тарифы'!$W$25
Name MeanMinAge02: '18_Календарь_тарифы'!$X$25
Name RevenueAge03: '18_Календарь_тарифы'!$B$26:$U$26
Name MinimumAge03: '18_Календарь_тарифы'!$B$56:$U$56
Name CapacityAge03: '18_Календарь_тарифы'!$W$26
Name MeanMinAge03: '18_Календарь_тарифы'!$X$26
Name RevenueAge04: '18_Календарь_тарифы'!$B$27:$U$27
Name MinimumAge04: '18_Календарь_тарифы'!$B$57:$U$57
Name CapacityAge04: '18_Календарь_тарифы'!$W$27
Name MeanMinAge04: '18_Календарь_тарифы'!$X$27
Name RevenueAge05: '18_Календарь_тарифы'!$B$28:$U$28
Name MinimumAge05: '18_Календарь_тарифы'!$B$58:$U$58
Name CapacityAge05: '18_Календарь_тарифы'!$W$28
Name MeanMinAge05: '18_Календарь_тарифы'!$X$28
Name RevenueAge06: '18_Календарь_тарифы'!$B$29:$U$29
Name MinimumAge06: '18_Календарь_тарифы'!$B$59:$U$59
Name CapacityAge06: '18_Календарь_тарифы'!$W$29
Name MeanMinAge06: '18_Календарь_тарифы'!$X$29
Name RevenueAge07: '18_Календарь_тарифы'!$B$30:$U$30
Name MinimumAge07: '18_Календарь_тарифы'!$B$60:$U$60
Name CapacityAge07: '18_Календарь_тарифы'!$W$30
Name MeanMinAge07: '18_Календарь_тарифы'!$X$30
Name RevenueAge08: '18_Календарь_тарифы'!$B$31:$U$31
Name MinimumAge08: '18_Календарь_тарифы'!$B$61:$U$61
Name CapacityAge08: '18_Календарь_тарифы'!$W$31
Name MeanMinAge08: '18_Календарь_тарифы'!$X$31
Name RevenueAge09: '18_Календарь_тарифы'!$B$32:$U$32
Name MinimumAge09: '18_Календарь_тарифы'!$B$62:$U$62
Name CapacityAge09: '18_Календарь_тарифы'!$W$32
Name MeanMinAge09: '18_Календарь_тарифы'!$X$32
Name RevenueAge10: '18_Календарь_тарифы'!$B$33:$U$33
Name MinimumAge10: '18_Календарь_тарифы'!$B$63:$U$63
Name CapacityAge10: '18_Календарь_тарифы'!$W$33
Name MeanMinAge10: '18_Календарь_тарифы'!$X$33
Name RevenueAge11: '18_Календарь_тарифы'!$B$34:$U$34
Name MinimumAge11: '18_Календарь_тарифы'!$B$64:$U$64
Name CapacityAge11: '18_Календарь_тарифы'!$W$34
Name MeanMinAge11: '18_Календарь_тарифы'!$X$34
Name RevenueAge12: '18_Календарь_тарифы'!$B$35:$U$35
Name MinimumAge12: '18_Календарь_тарифы'!$B$65:$U$65
Name CapacityAge12: '18_Календарь_тарифы'!$W$35
Name MeanMinAge12: '18_Календарь_тарифы'!$X$35
Name RevenueAge13: '18_Календарь_тарифы'!$B$36:$U$36
Name MinimumAge13: '18_Календарь_тарифы'!$B$66:$U$66
Name CapacityAge13: '18_Календарь_тарифы'!$W$36
Name MeanMinAge13: '18_Календарь_тарифы'!$X$36
Name RevenueAge14: '18_Календарь_тарифы'!$B$37:$U$37
Name MinimumAge14: '18_Календарь_тарифы'!$B$67:$U$67
Name CapacityAge14: '18_Календарь_тарифы'!$W$37
Name MeanMinAge14: '18_Календарь_тарифы'!$X$37
Name RevenueAge15: '18_Календарь_тарифы'!$B$38:$U$38
Name MinimumAge15: '18_Календарь_тарифы'!$B$68:$U$68
Name CapacityAge15: '18_Календарь_тарифы'!$W$38
Name MeanMinAge15: '18_Календарь_тарифы'!$X$38

Sheet 00_Старт
A1: СПАРТАК · финансовая модель — с чего начать
A2: Три действия: посмотреть результат → поменять вводные → проверить сходимость. Считать вручную ничего не нужно.
A4: ШАГ 1 · Что уже посчитано | D4: все суммы в млн ₽, если не указано иное
A5: Показатель | B5: Значение | C5: Ед. | D5: Что это значит
A6: Активный сценарий | B6: ='01_Вводные'!$B$192 | D6: Меняется на 01_Вводные!B192. Пересчитывает всю книгу.
A7: Старт горизонта | B7: ='01_Вводные'!$B$7 | D7: Дальше 60 месяцев. Сезон = сентябрь–август.
A8: Выручка без НДС, 5 сезонов | B8: ='00_Дашборд'!$H$24/1000000 | C8: млн ₽ | D8: Паушальные + роялти + мерч + лагеря.
A9: EBITDA, 5 сезонов | B9: ='00_Дашборд'!$H$29/1000000 | C9: млн ₽ | D9: До налога УСН, до CAPEX и до возврата займа.
A10: Рентабельность EBITDA | B10: ='00_Дашборд'!$H$30 | C10: % | D10: EBITDA / выручка без НДС за весь горизонт.
A11: Деньги на конец горизонта | B11: ='00_Дашборд'!$H$32/1000000 | C11: млн ₽ | D11: Остаток на счёте в последнем месяце.
A12: Пиковый кассовый дефицит | B12: ='00_Дашборд'!$H$38/1000000 | C12: млн ₽ | D12: Максимальный минус на счёте. Кредит на его покрытие в модель НЕ заложен.
A13: Нехватка товара (по COGS) | B13: ='13_Проверки'!$B$41/1000000 | C13: млн ₽ | D13: Если > 0 — план продаж не обеспечен запасом формы.
A14: Операционные выплаты ФК | B14: ='00_Дашборд'!$H$37/1000000 | C14: млн ₽ | D14: Деньгами: доли от паушальных, роялти и прибыли мерча.
A15: Возврат займа ФК | B15: ='00_Дашборд'!$H$34/1000000 | C15: млн ₽ | D15: Тело займа на мерч, отдельно от операционных выплат.
A16: Займ на конец | B16: ='00_Дашборд'!$H$35/1000000 | C16: млн ₽ | D16: Непогашенный остаток стартового займа 50 млн ₽.
A17: CAPEX за горизонт | B17: ='00_Дашборд'!$H$39/1000000 | C17: млн ₽ | D17: 1% выручки с НДС + разовый CAPEX.
A18: Активные школы на конец | B18: ='00_Дашборд'!$G$20 | D18: Действующая сеть + новые школы.
A19: Продано франшиз за 5 сезонов | B19: ='00_Дашборд'!$H$17 | D19: Финансовый план; целые продажи — на 04_Продажи.
A21: ШАГ 2 · Что можно менять | D21: правим ТОЛЬКО жёлтые ячейки на 01_Вводные
A22: Переключатель | B22: Сейчас | C22: Где | D22: Что произойдёт
A23: Сценарий | B23: ='01_Вводные'!$B$192 | C23: B192 | D23: Меняет 6 драйверов сразу: план продаж, детей, цену абонемента, мерч, таргет, срок роялти.
A24: Режим просмотра итога | B24: ='01_Вводные'!$B$188 | C24: B188 | D24: Добавляет к прогнозу фактический сезон 25/26. На формулы прогноза не влияет.
A25: Драйвер чувствительности | B25: ='01_Вводные'!$B$233 | C25: B233 | D25: Что именно тестируем на 12_Чувствительность.
A26: Чувствительность включена | B26: ='01_Вводные'!$B$234 | C26: B234 | D26: «Нет» отключает два дополнительных прогона — книга считается быстрее.
A27: Лагеря включены | B27: ='01_Вводные'!$B$241 | C27: B241 | D27: «Нет» обнуляет продажи, начисления и оплаты лагерей.
A28: CAPEX включён | B28: ='01_Вводные'!$B$290 | C28: B290 | D28: «Нет» убирает CAPEX из денег до погашения займа.
A29: Индексация вне ФОТ | B29: ='01_Вводные'!$B$294 | C29: B294 | D29: Абонемент, паушальный, форма, ERP, IT, юристы, реклама. Офис и мин. роялти не индексируются.
A30: Постепенный набор детей | B30: ='01_Вводные'!$B$295 | C30: B295 | D30: Школа выходит на план за 12 месяцев, потом на план 2-го года за 13–24.
A31: Роялти по тарифным группам | B31: ='01_Вводные'!$B$239 | C31: B239 | D31: «Да» — минимум проверяется по каждой школе своего тарифа. «Нет» — прежнее усреднение, только для сверки.
A32: Возврат займа ограничен запасом | B32: ='01_Вводные'!$B$238 | C32: B238 | D32: п.27 ТЗ: гасим займ только если склад не ниже цели будущих месяцев.
A34: Числовые вводные (цены, оклады, ставки, планы продаж) — там же, на 01_Вводные, по разделам 1–16.
A35: Базы сценарных драйверов (план продаж, мощность школы, абонемент, мерч, таргет, дебиторка) — 01_Вводные!B210:B225.
A37: ШАГ 3 · Проверить, что модель сошлась
A38: Пройдено автопроверок | B38: =COUNTIF('13_Проверки'!$C$4:$C$68,"OK") | D38: Тесты сходимости БДР↔БДДС, склада, займа, сценариев.
A39: Требует проверки | B39: =COUNTIF('13_Проверки'!$C$4:$C$68,"ПРОВЕРИТЬ") | D39: Должно быть 0. Если больше — открой 13_Проверки.
A40: Риск плана | B40: =COUNTIF('13_Проверки'!$C$4:$C$68,"РИСК ПЛАНА") | D40: Не ошибка формул: нехватка денег или товара показана честно.
A41: Сознательное упрощение | B41: =COUNTIF('13_Проверки'!$C$4:$C$68,"УПРОЩЕНИЕ") | D41: Включён упрощённый режим расчёта (например, роялти без тарифов).
A42: Итог | B42: =IF(COUNTIF('13_Проверки'!$C$4:$C$68,"ПРОВЕРИТЬ")=0,"Модель сходится","Есть расхождения") | C42: 13_Проверки
A44: Цвета ячеек
A45: Жёлтая | D45: Обычная вводная. Можно и нужно менять.
...

Sheet 00_Дашборд
A1: Финмодель Спартак — управленческий дашборд
A3: Как работать | B3: Все ручные вводные находятся только на листе 01_Вводные. Остальные листы — расчётные. Жёлтый = ввод, чёрный/зелёный = формулы и связи. | J3: Быстрая навигация
J4: → Вводные
A5: Ключевые вводные | J5: → Основная модель
A6: Старт модели | B6: ='01_Вводные'!$B$7 | D6: Сценарий | E6: ='01_Вводные'!B192 | G6: Контроль модели | J6: → Сценарии
A7: Стартовые юрлица | B7: ='01_Вводные'!$B$10 | D7: Сравнение | E7: 03_Сценарии | G7: Провалено автопроверок | H7: =COUNTIF('13_Проверки'!C4:C68,"ПРОВЕРИТЬ") | J7: → Продажи / воронка
A8: Стартовые школы | B8: ='01_Вводные'!$B$9 | D8: Чувствительность | E8: 12_Чувствительность | G8: Статус | H8: =IF(COUNTIF('13_Проверки'!C4:C68,"ПРОВЕРИТЬ")=0,"Сходится","Открой 13_Проверки") | J8: → Сеть и дети
A9: Дети действующей сети, 100% | B9: ='01_Вводные'!$B$11 | G9: Пиковый кассовый дефицит, ₽ | H9: =E12 | J9: → Мерч / склад
A10: Лаг открытия | B10: ='01_Вводные'!$B$15 | D10: Проверки | E10: 13_Проверки | G10: Нехватка товара, ₽ COGS | H10: =E11 | J10: → ФОТ
A11: Стартовый склад | B11: ='01_Вводные'!$B$77 | D11: Дефицит товара | E11: =MAX('07_Мерч'!B27:BI27) | G11: → Начать здесь: 00_Старт | J11: → Выплаты ФК
A12: Стартовый займ | B12: ='01_Вводные'!$B$78 | D12: Кассовый дефицит | E12: =MAX(0,-MIN('02_Модель'!B72:BI72)) | J12: → Проверки
A15: Итоги по сезонам
A16: Показатель | B16: 25/26 факт* | C16: 26/27 | D16: 27/28 | E16: 28/29 | F16: 29/30 | G16: 30/31 | H16: Итого прогноз
A17: Продажи франшиз | C17: =SUM('04_Продажи'!B15:M15) | D17: =SUM('04_Продажи'!N15:Y15) | E17: =SUM('04_Продажи'!Z15:AK15) | F17: =SUM('04_Продажи'!AL15:AW15) | G17: =SUM('04_Продажи'!AX15:BI15) | H17: =SUM(C17:G17)
A18: Открытия школ | C18: =SUM('04_Продажи'!B18:M18) | D18: =SUM('04_Продажи'!N18:Y18) | E18: =SUM('04_Продажи'!Z18:AK18) | F18: =SUM('04_Продажи'!AL18:AW18) | G18: =SUM('04_Продажи'!AX18:BI18) | H18: =SUM(C18:G18)
A19: Активные юрлица, конец | C19: ='02_Модель'!M13 | D19: ='02_Модель'!Y13 | E19: ='02_Модель'!AK13 | F19: ='02_Модель'!AW13 | G19: ='02_Модель'!BI13 | H19: =G19
A20: Активные школы, конец | C20: ='02_Модель'!M9+'02_Модель'!M12 | D20: ='02_Модель'!Y9+'02_Модель'!Y12 | E20: ='02_Модель'!AK9+'02_Модель'!AK12 | F20: ='02_Модель'!AW9+'02_Модель'!AW12 | G20: ='02_Модель'!BI9+'02_Модель'!BI12 | H20: =G20
A21: Дети действующей сети, среднее | C21: =AVERAGE('02_Модель'!B11:M11) | D21: =AVERAGE('02_Модель'!N11:Y11) | E21: =AVERAGE('02_Модель'!Z11:AK11) | F21: =AVERAGE('02_Модель'!AL11:AW11) | G21: =AVERAGE('02_Модель'!AX11:BI11) | H21: =AVERAGE('02_Модель'!B11:BI11)
A22: Дети новых школ, среднее | C22: =AVERAGE('02_Модель'!B14:M14) | D22: =AVERAGE('02_Модель'!N14:Y14) | E22: =AVERAGE('02_Модель'!Z14:AK14) | F22: =AVERAGE('02_Модель'!AL14:AW14) | G22: =AVERAGE('02_Модель'!AX14:BI14) | H22: =AVERAGE('02_Модель'!B14:BI14)
A23: Дети всего, среднее | C23: =AVERAGE('02_Модель'!B15:M15) | D23: =AVERAGE('02_Модель'!N15:Y15) | E23: =AVERAGE('02_Модель'!Z15:AK15) | F23: =AVERAGE('02_Модель'!AL15:AW15) | G23: =AVERAGE('02_Модель'!AX15:BI15) | H23: =AVERAGE('02_Модель'!B15:BI15)
A24: Выручка без НДС | B24: ='11_История_25_26'!N4 | C24: =SUM('02_Модель'!B23:M23) | D24: =SUM('02_Модель'!N23:Y23) | E24: =SUM('02_Модель'!Z23:AK23) | F24: =SUM('02_Модель'!AL23:AW23) | G24: =SUM('02_Модель'!AX23:BI23) | H24: =SUM(C24:G24)
A25: Паушальные взносы | C25: =SUM('02_Модель'!B18:M18) | D25: =SUM('02_Модель'!N18:Y18) | E25: =SUM('02_Модель'!Z18:AK18) | F25: =SUM('02_Модель'!AL18:AW18) | G25: =SUM('02_Модель'!AX18:BI18) | H25: =SUM(C25:G25)
A26: Роялти | C26: =SUM('02_Модель'!B19:M20) | D26: =SUM('02_Модель'!N19:Y20) | E26: =SUM('02_Модель'!Z19:AK20) | F26: =SUM('02_Модель'!AL19:AW20) | G26: =SUM('02_Модель'!AX19:BI20) | H26: =SUM(C26:G26)
A27: Мерч | C27: =SUM('02_Модель'!B21:M21) | D27: =SUM('02_Модель'!N21:Y21) | E27: =SUM('02_Модель'!Z21:AK21) | F27: =SUM('02_Модель'!AL21:AW21) | G27: =SUM('02_Модель'!AX21:BI21) | H27: =SUM(C27:G27)
A28: Лагеря | C28: =SUM('02_Модель'!B22:M22) | D28: =SUM('02_Модель'!N22:Y22) | E28: =SUM('02_Модель'!Z22:AK22) | F28: =SUM('02_Модель'!AL22:AW22) | G28: =SUM('02_Модель'!AX22:BI22) | H28: =SUM(C28:G28)
A29: EBITDA | B29: ='11_История_25_26'!N9 | C29: =SUM('02_Модель'!B44:M44) | D29: =SUM('02_Модель'!N44:Y44) | E29: =SUM('02_Модель'!Z44:AK44) | F29: =SUM('02_Модель'!AL44:AW44) | G29: =SUM('02_Модель'!AX44:BI44) | H29: =SUM(C29:G29)
A30: EBITDA margin | C30: =IF(SUM('02_Модель'!B23:M23)=0,0,SUM('02_Модель'!B44:M44)/SUM('02_Модель'!B23:M23)) | D30: =IF(SUM('02_Модель'!N23:Y23)=0,0,SUM('02_Модель'!N44:Y44)/SUM('02_Модель'!N23:Y23)) | E30: =IF(SUM('02_Модель'!Z23:AK23)=0,0,SUM('02_Модель'!Z44:AK44)/SUM('02_Модель'!Z23:AK23)) | F30: =IF(SUM('02_Модель'!AL23:AW23)=0,0,SUM('02_Модель'!AL44:AW44)/SUM('02_Модель'!AL23:AW23)) | G30: =IF(SUM('02_Модель'!AX23:BI23)=0,0,SUM('02_Модель'!AX44:BI44)/SUM('02_Модель'!AX23:BI23)) | H30: =IF(H24=0,0,H29/H24)
A31: Чистый денежный поток | C31: =SUM('02_Модель'!B71:M71) | D31: =SUM('02_Модель'!N71:Y71) | E31: =SUM('02_Модель'!Z71:AK71) | F31: =SUM('02_Модель'!AL71:AW71) | G31: =SUM('02_Модель'!AX71:BI71) | H31: =SUM(C31:G31)
A32: Деньги на конец | C32: ='02_Модель'!M72 | D32: ='02_Модель'!Y72 | E32: ='02_Модель'!AK72 | F32: ='02_Модель'!AW72 | G32: ='02_Модель'!BI72 | H32: =G32
A33: Закупки на склад | C33: =SUM('02_Модель'!B65:M65) | D33: =SUM('02_Модель'!N65:Y65) | E33: =SUM('02_Модель'!Z65:AK65) | F33: =SUM('02_Модель'!AL65:AW65) | G33: =SUM('02_Модель'!AX65:BI65) | H33: =SUM(C33:G33)
A34: Погашение займа | C34: =SUM('02_Модель'!B70:M70) | D34: =SUM('02_Модель'!N70:Y70) | E34: =SUM('02_Модель'!Z70:AK70) | F34: =SUM('02_Модель'!AL70:AW70) | G34: =SUM('02_Модель'!AX70:BI70) | H34: =SUM(C34:G34)
A35: Конечный займ | C35: ='02_Модель'!M75 | D35: ='02_Модель'!Y75 | E35: ='02_Модель'!AK75 | F35: ='02_Модель'!AW75 | G35: ='02_Модель'!BI75 | H35: =G35
A36: Конечный склад | C36: ='02_Модель'!M76 | D36: ='02_Модель'!Y76 | E36: ='02_Модель'!AK76 | F36: ='02_Модель'!AW76 | G36: ='02_Модель'!BI76 | H36: =G36
A37: Операционные выплаты ФК, деньги | C37: =SUM('02_Модель'!B61:M61) | D37: =SUM('02_Модель'!N61:Y61) | E37: =SUM('02_Модель'!Z61:AK61) | F37: =SUM('02_Модель'!AL61:AW61) | G37: =SUM('02_Модель'!AX61:BI61) | H37: =SUM(C37:G37)
A38: Пиковый кассовый дефицит | C38: =MAX(0,-MIN('02_Модель'!B72:M72)) | D38: =MAX(0,-MIN('02_Модель'!N72:Y72)) | E38: =MAX(0,-MIN('02_Модель'!Z72:AK72)) | F38: =MAX(0,-MIN('02_Модель'!AL72:AW72)) | G38: =MAX(0,-MIN('02_Модель'!AX72:BI72)) | H38: =MAX(0,-MIN('02_Модель'!B72:BI72))
A39: CAPEX — всего | C39: =SUM('02_Модель'!B57:M57) | D39: =SUM('02_Модель'!N57:Y57) | E39: =SUM('02_Модель'!Z57:AK57) | F39: =SUM('02_Модель'!AL57:AW57) | G39: =SUM('02_Модель'!AX57:BI57) | H39: =SUM(C39:G39)
A40: Результат с историей / без истории
A41: Режим просмотра | B41: ='01_Вводные'!B188
A42: Выручка, выбранный период | B42: =IF('01_Вводные'!B188="С историей",B24+H24,H24)
A43: EBITDA, выбранный период | B43: =IF('01_Вводные'!B188="С историей",B29+H29,H29)
...

Sheet 01_Вводные
A1: Финмодель Спартак — единый лист вводных
A2: Легенда: | B2: ввод | C2: уточнить | D2: переключатель | E2: блок ревизии | F2: формула — не трогать | G2: → 00_Старт: оглавление, переключатели, легенда | H2: → 14а_Сверка_с_ТЗ: пункт ТЗ → формула
A3: Правило работы | B3: Менять жёлтые ячейки только здесь. Сценарий: B192. Чувствительность: B233:B234. Параметры, микс и история собраны на одном листе.
A4: Сценарии и чувствительность | G4: → Раздел 11: сценарии и чувствительность | H4: → Раздел 13: тарифные группы
A5: 1. Календарь, стартовая сеть и оборотный капитал
A6: Параметр | B6: Значение | C6: Ед. | D6: Статус / источник | E6: Комментарий | G6: → Раздел 12: настройки ревизии | H6: → Раздел 14: CAPEX и индексация
A7: Дата старта модели | B7: 46266 | C7: дата | D7: ТЗ 5.1 | E7: Сезон считается от даты старта: 12 месяцев — один сезон. Сезонность посещаемости, веса плана продаж и согласованный мерч привязаны к календарю и не зависят от месяца старта.
A8: Горизонт прогноза | B8: 60 | C8: мес. | D8: Фиксированная структура | E8: Фиксированное окно 60 месяцев + 6 технических. Изменение длины требует расширения структуры. | G8: → Раздел 15–16: займ, открытие школ, роялти по группам | H8: → Раздел 17: история сезона 25/26
A9: Активные школы действующей сети на старте | B9: 104 | C9: шт. | D9: Фактический реестр на 09.09.2026 | E9: 104 действующие школы у 51 действующего партнёра; 3 новых партнёра пока без школ и в 104 не входят.
A10: Активные юрлица на старте | B10: 51 | C10: шт. | D10: Реестр сети 21.08.2026 | E10: 51 действующий партнёр: 48 подписали ДКК, 3 в переговорах. В ТЗ v6.011 указано 49 — цифра реестра точнее, подтверждена 11.09.2026.
A11: Дети действующей сети, 100% база | B11: 5200 | C11: чел. | D11: ТЗ 5.3 | E11: 100% загрузка; внутри сезона применяется посещаемость
A12: Рост детей действующей сети | B12: 0.1 | C12: %/год | D12: ТЗ 5.3 | E12: Сложный рост, пересчёт каждый сентябрь
A13: Закрытие школ / юрлиц | B13: 0.03 | C13: %/год | D13: Согласовано 11.09.2026 | E13: =IF($B$13=0,"Механика работает, пока 0%","Закрывается "&ROUND($B$13*100,1)&" % школ и юрлиц в год; помесячно через коэффициент B14")
A14: Месячный коэффициент сохранения | B14: =(1-B13)^(1/12) | C14: коэфф. | D14: Расчёт | E14: Технический коэффициент для закрытий
A15: Лаг продажа → открытие | B15: 2 | C15: мес. | D15: ТЗ 5.2 | E15: Продажа, открытие и ERP — разные события
A16: Новых юрлиц на 1 продажу | B16: 1 | C16: юрлиц/продажу | D16: Временно | E16: Связь продаж с новыми юрлицами. Пока 1:1; отдельно от количества школ на партнёра.
A17: Стартовый денежный остаток | B17: 187878 | C17: ₽ | D17: ДДС на 02.07.2026 | E17: Обновить на 31.08.2026
A18: Дебиторка | B18: =$B$225*$F$203 | C18: дней | D18: Расчет по сценарию | E18: Базовое допущение | G18: ← формула; база: B225
A19: Кредиторка | B19: 15 | C19: дней | D19: ТЗ 8 | E19: Базовое допущение
A20: Доля поступления в текущем месяце | B20: =MAX(0,MIN(1,(30-B18)/30)) | C20: % | D20: Расчёт | E20: 15 дней ≈ 50% текущий / 50% следующий месяц
A21: Доля оплаты в текущем месяце | B21: =MAX(0,MIN(1,(30-B19)/30)) | C21: % | D21: Расчёт | E21: 15 дней ≈ 50% текущий / 50% следующий месяц
A22: Новых школ на 1 продажу / нового партнёра | B22: 1.5 | C22: школ/продажу | D22: Согласовано 11.09.2026 | E22: ="Новый партнёр открывает "&ROUND($B$22,1)&" школы. Действующая сеть: 2,04 школы на партнёра (104 на 51)"
A23: 2. Продажи франшиз и маркетинг
A24: Параметр | B24: Значение | C24: Ед. | D24: Статус / источник | E24: Комментарий
A25: Конверсия лид → продажа | B25: 0.03 | C25: % | D25: ТЗ 7
A26: Таргет на будущую продажу | B26: =$B$224*$F$202 | C26: ₽/продажа | D26: Расчет по сценарию | E26: Обычно M-2; для октября 2026 исключение M-1 | G26: ← формула; база: B224
A27: Лаг таргета до продажи | B27: 2 | C27: мес. | D27: ТЗ 7 | E27: Октябрь 2026 — отдельное исключение
A28: БИБОСС — сумма | B28: 250000 | C28: ₽ | D28: ТЗ 7 | E28: Ежегодно
A29: БИБОСС — месяц | B29: 10 | C29: номер месяца | D29: ТЗ 7 | E29: Октябрь
A30: TopFranchise — сумма | B30: 250000 | C30: ₽ | D30: ТЗ 7 | E30: Ежегодно
A31: TopFranchise — месяц | B31: 11 | C31: номер месяца | D31: ТЗ 7 | E31: Ноябрь
A32: Forbes — сумма | B32: 250000 | C32: ₽ | D32: ТЗ 7 | E32: Ежегодно
A33: Forbes — месяц | B33: 12 | C33: номер месяца | D33: ТЗ 7 | E33: Декабрь
A34: 2а. Планы продаж и сезонность (веса — по календарным месяцам, первый месяц модели без продаж)
A35: Сезон | B35: Годовой план | C35: Сен | D35: Окт | E35: Ноя | F35: Дек | G35: Янв | H35: Фев | I35: Мар | J35: Апр | K35: Май | L35: Июн | M35: Июл | N35: Авг | O35: Контроль
A36: 1 | B36: =$B$210*$F$198 | C36: 0.18 | D36: 0.09 | E36: 0.03 | F36: 0.02 | G36: 0.08 | H36: 0.13 | I36: 0.05 | J36: 0.06 | K36: 0.08 | L36: 0.05 | M36: 0.09 | N36: 0.14 | O36: =SUM(C36:N36)
A37: 2 | B37: =$B$211*$F$198 | C37: 0.18 | D37: 0.09 | E37: 0.03 | F37: 0.02 | G37: 0.08 | H37: 0.13 | I37: 0.05 | J37: 0.06 | K37: 0.08 | L37: 0.05 | M37: 0.09 | N37: 0.14 | O37: =SUM(C37:N37)
A38: 3 | B38: =$B$212*$F$198 | C38: 0.18 | D38: 0.09 | E38: 0.03 | F38: 0.02 | G38: 0.08 | H38: 0.13 | I38: 0.05 | J38: 0.06 | K38: 0.08 | L38: 0.05 | M38: 0.09 | N38: 0.14 | O38: =SUM(C38:N38)
A39: 4 | B39: =$B$213*$F$198 | C39: 0.18 | D39: 0.09 | E39: 0.03 | F39: 0.02 | G39: 0.08 | H39: 0.13 | I39: 0.05 | J39: 0.06 | K39: 0.08 | L39: 0.05 | M39: 0.09 | N39: 0.14 | O39: =SUM(C39:N39)
A40: 5 | B40: =$B$214*$F$198 | C40: 0.18 | D40: 0.09 | E40: 0.03 | F40: 0.02 | G40: 0.08 | H40: 0.13 | I40: 0.05 | J40: 0.06 | K40: 0.08 | L40: 0.05 | M40: 0.09 | N40: 0.14 | O40: =SUM(C40:N40)
...

Sheet 02_Модель
A1: Помесячная модель — БДР и БДДС
B3: =DATE(YEAR('01_Вводные'!$B$7),MONTH('01_Вводные'!$B$7)+0,1) | C3: =DATE(YEAR('01_Вводные'!$B$7),MONTH('01_Вводные'!$B$7)+1,1) | D3: =DATE(YEAR('01_Вводные'!$B$7),MONTH('01_Вводные'!$B$7)+2,1) | E3: =DATE(YEAR('01_Вводные'!$B$7),MONTH('01_Вводные'!$B$7)+3,1) | F3: =DATE(YEAR('01_Вводные'!$B$7),MONTH('01_Вводные'!$B$7)+4,1) | G3: =DATE(YEAR('01_Вводные'!$B$7),MONTH('01_Вводные'!$B$7)+5,1) | H3: =DATE(YEAR('01_Вводные'!$B$7),MONTH('01_Вводные'!$B$7)+6,1) | I3: =DATE(YEAR('01_Вводные'!$B$7),MONTH('01_Вводные'!$B$7)+7,1) | J3: =DATE(YEAR('01_Вводные'!$B$7),MONTH('01_Вводные'!$B$7)+8,1) | K3: =DATE(YEAR('01_Вводные'!$B$7),MONTH('01_Вводные'!$B$7)+9,1) | L3: =DATE(YEAR('01_Вводные'!$B$7),MONTH('01_Вводные'!$B$7)+10,1) | M3: =DATE(YEAR('01_Вводные'!$B$7),MONTH('01_Вводные'!$B$7)+11,1) | N3: =DATE(YEAR('01_Вводные'!$B$7),MONTH('01_Вводные'!$B$7)+12,1) | O3: =DATE(YEAR('01_Вводные'!$B$7),MONTH('01_Вводные'!$B$7)+13,1) | P3: =DATE(YEAR('01_Вводные'!$B$7),MONTH('01_Вводные'!$B$7)+14,1) | Q3: =DATE(YEAR('01_Вводные'!$B$7),MONTH('01_Вводные'!$B$7)+15,1) | R3: =DATE(YEAR('01_Вводные'!$B$7),MONTH('01_Вводные'!$B$7)+16,1) | S3: =DATE(YEAR('01_Вводные'!$B$7),MONTH('01_Вводные'!$B$7)+17,1) | T3: =DATE(YEAR('01_Вводные'!$B$7),MONTH('01_Вводные'!$B$7)+18,1) | U3: =DATE(YEAR('01_Вводные'!$B$7),MONTH('01_Вводные'!$B$7)+19,1) | V3: =DATE(YEAR('01_Вводные'!$B$7),MONTH('01_Вводные'!$B$7)+20,1) | W3: =DATE(YEAR('01_Вводные'!$B$7),MONTH('01_Вводные'!$B$7)+21,1) | X3: =DATE(YEAR('01_Вводные'!$B$7),MONTH('01_Вводные'!$B$7)+22,1) | Y3: =DATE(YEAR('01_Вводные'!$B$7),MONTH('01_Вводные'!$B$7)+23,1) | Z3: =DATE(YEAR('01_Вводные'!$B$7),MONTH('01_Вводные'!$B$7)+24,1) | AA3: =DATE(YEAR('01_Вводные'!$B$7),MONTH('01_Вводные'!$B$7)+25,1) | AB3: =DATE(YEAR('01_Вводные'!$B$7),MONTH('01_Вводные'!$B$7)+26,1) | AC3: =DATE(YEAR('01_Вводные'!$B$7),MONTH('01_Вводные'!$B$7)+27,1) | AD3: =DATE(YEAR('01_Вводные'!$B$7),MONTH('01_Вводные'!$B$7)+28,1) | AE3: =DATE(YEAR('01_Вводные'!$B$7),MONTH('01_Вводные'!$B$7)+29,1) | AF3: =DATE(YEAR('01_Вводные'!$B$7),MONTH('01_Вводные'!$B$7)+30,1) | AG3: =DATE(YEAR('01_Вводные'!$B$7),MONTH('01_Вводные'!$B$7)+31,1) | AH3: =DATE(YEAR('01_Вводные'!$B$7),MONTH('01_Вводные'!$B$7)+32,1) | AI3: =DATE(YEAR('01_Вводные'!$B$7),MONTH('01_Вводные'!$B$7)+33,1) | AJ3: =DATE(YEAR('01_Вводные'!$B$7),MONTH('01_Вводные'!$B$7)+34,1) | AK3: =DATE(YEAR('01_Вводные'!$B$7),MONTH('01_Вводные'!$B$7)+35,1) | AL3: =DATE(YEAR('01_Вводные'!$B$7),MONTH('01_Вводные'!$B$7)+36,1) | AM3: =DATE(YEAR('01_Вводные'!$B$7),MONTH('01_Вводные'!$B$7)+37,1) | AN3: =DATE(YEAR('01_Вводные'!$B$7),MONTH('01_Вводные'!$B$7)+38,1) | AO3: =DATE(YEAR('01_Вводные'!$B$7),MONTH('01_Вводные'!$B$7)+39,1) | AP3: =DATE(YEAR('01_Вводные'!$B$7),MONTH('01_Вводные'!$B$7)+40,1) | AQ3: =DATE(YEAR('01_Вводные'!$B$7),MONTH('01_Вводные'!$B$7)+41,1) | AR3: =DATE(YEAR('01_Вводные'!$B$7),MONTH('01_Вводные'!$B$7)+42,1) | AS3: =DATE(YEAR('01_Вводные'!$B$7),MONTH('01_Вводные'!$B$7)+43,1) | AT3: =DATE(YEAR('01_Вводные'!$B$7),MONTH('01_Вводные'!$B$7)+44,1) | AU3: =DATE(YEAR('01_Вводные'!$B$7),MONTH('01_Вводные'!$B$7)+45,1) | AV3: =DATE(YEAR('01_Вводные'!$B$7),MONTH('01_Вводные'!$B$7)+46,1) | AW3: =DATE(YEAR('01_Вводные'!$B$7),MONTH('01_Вводные'!$B$7)+47,1) | AX3: =DATE(YEAR('01_Вводные'!$B$7),MONTH('01_Вводные'!$B$7)+48,1) | AY3: =DATE(YEAR('01_Вводные'!$B$7),MONTH('01_Вводные'!$B$7)+49,1) | AZ3: =DATE(YEAR('01_Вводные'!$B$7),MONTH('01_Вводные'!$B$7)+50,1) | BA3: =DATE(YEAR('01_Вводные'!$B$7),MONTH('01_Вводные'!$B$7)+51,1) | BB3: =DATE(YEAR('01_Вводные'!$B$7),MONTH('01_Вводные'!$B$7)+52,1) | BC3: =DATE(YEAR('01_Вводные'!$B$7),MONTH('01_Вводные'!$B$7)+53,1) | BD3: =DATE(YEAR('01_Вводные'!$B$7),MONTH('01_Вводные'!$B$7)+54,1) | BE3: =DATE(YEAR('01_Вводные'!$B$7),MONTH('01_Вводные'!$B$7)+55,1) | BF3: =DATE(YEAR('01_Вводные'!$B$7),MONTH('01_Вводные'!$B$7)+56,1) | BG3: =DATE(YEAR('01_Вводные'!$B$7),MONTH('01_Вводные'!$B$7)+57,1) | BH3: =DATE(YEAR('01_Вводные'!$B$7),MONTH('01_Вводные'!$B$7)+58,1) | BI3: =DATE(YEAR('01_Вводные'!$B$7),MONTH('01_Вводные'!$B$7)+59,1)
B4: =INT((0)/12)+1 | C4: =INT((1)/12)+1 | D4: =INT((2)/12)+1 | E4: =INT((3)/12)+1 | F4: =INT((4)/12)+1 | G4: =INT((5)/12)+1 | H4: =INT((6)/12)+1 | I4: =INT((7)/12)+1 | J4: =INT((8)/12)+1 | K4: =INT((9)/12)+1 | L4: =INT((10)/12)+1 | M4: =INT((11)/12)+1 | N4: =INT((12)/12)+1 | O4: =INT((13)/12)+1 | P4: =INT((14)/12)+1 | Q4: =INT((15)/12)+1 | R4: =INT((16)/12)+1 | S4: =INT((17)/12)+1 | T4: =INT((18)/12)+1 | U4: =INT((19)/12)+1 | V4: =INT((20)/12)+1 | W4: =INT((21)/12)+1 | X4: =INT((22)/12)+1 | Y4: =INT((23)/12)+1 | Z4: =INT((24)/12)+1 | AA4: =INT((25)/12)+1 | AB4: =INT((26)/12)+1 | AC4: =INT((27)/12)+1 | AD4: =INT((28)/12)+1 | AE4: =INT((29)/12)+1 | AF4: =INT((30)/12)+1 | AG4: =INT((31)/12)+1 | AH4: =INT((32)/12)+1 | AI4: =INT((33)/12)+1 | AJ4: =INT((34)/12)+1 | AK4: =INT((35)/12)+1 | AL4: =INT((36)/12)+1 | AM4: =INT((37)/12)+1 | AN4: =INT((38)/12)+1 | AO4: =INT((39)/12)+1 | AP4: =INT((40)/12)+1 | AQ4: =INT((41)/12)+1 | AR4: =INT((42)/12)+1 | AS4: =INT((43)/12)+1 | AT4: =INT((44)/12)+1 | AU4: =INT((45)/12)+1 | AV4: =INT((46)/12)+1 | AW4: =INT((47)/12)+1 | AX4: =INT((48)/12)+1 | AY4: =INT((49)/12)+1 | AZ4: =INT((50)/12)+1 | BA4: =INT((51)/12)+1 | BB4: =INT((52)/12)+1 | BC4: =INT((53)/12)+1 | BD4: =INT((54)/12)+1 | BE4: =INT((55)/12)+1 | BF4: =INT((56)/12)+1 | BG4: =INT((57)/12)+1 | BH4: =INT((58)/12)+1 | BI4: =INT((59)/12)+1
A5: Операционные драйверы
A6: Сезон | B6: ='06_Сеть_и_дети'!B4 | C6: ='06_Сеть_и_дети'!C4 | D6: ='06_Сеть_и_дети'!D4 | E6: ='06_Сеть_и_дети'!E4 | F6: ='06_Сеть_и_дети'!F4 | G6: ='06_Сеть_и_дети'!G4 | H6: ='06_Сеть_и_дети'!H4 | I6: ='06_Сеть_и_дети'!I4 | ... BI6: ='06_Сеть_и_дети'!BI4
A7: Сезонность посещаемости | B7: ='06_Сеть_и_дети'!B5 | C7: ='06_Сеть_и_дети'!C5 | D7: ='06_Сеть_и_дети'!D5 | E7: ='06_Сеть_и_дети'!E5 | F7: ='06_Сеть_и_дети'!F5 | G7: ='06_Сеть_и_дети'!G5 | H7: ='06_Сеть_и_дети'!H5 | I7: ='06_Сеть_и_дети'!I5 | ... BI7: ='06_Сеть_и_дети'!BI5
A9: Действующая сеть — школы | B9: ='06_Сеть_и_дети'!B11 | C9: ='06_Сеть_и_дети'!C11 | D9: ='06_Сеть_и_дети'!D11 | E9: ='06_Сеть_и_дети'!E11 | F9: ='06_Сеть_и_дети'!F11 | G9: ='06_Сеть_и_дети'!G11 | H9: ='06_Сеть_и_дети'!H11 | I9: ='06_Сеть_и_дети'!I11 | ... BI9: ='06_Сеть_и_дети'!BI11
A10: Действующая сеть — дети 100% база | B10: ='06_Сеть_и_дети'!B19 | C10: ='06_Сеть_и_дети'!C19 | D10: ='06_Сеть_и_дети'!D19 | E10: ='06_Сеть_и_дети'!E19 | F10: ='06_Сеть_и_дети'!F19 | G10: ='06_Сеть_и_дети'!G19 | H10: ='06_Сеть_и_дети'!H19 | I10: ='06_Сеть_и_дети'!I19 | ... BI10: ='06_Сеть_и_дети'!BI19
A11: Действующая сеть — активные дети | B11: ='06_Сеть_и_дети'!B20 | C11: ='06_Сеть_и_дети'!C20 | D11: ='06_Сеть_и_дети'!D20 | E11: ='06_Сеть_и_дети'!E20 | F11: ='06_Сеть_и_дети'!F20 | G11: ='06_Сеть_и_дети'!G20 | H11: ='06_Сеть_и_дети'!H20 | I11: ='06_Сеть_и_дети'!I20 | ... BI11: ='06_Сеть_и_дети'!BI20
A12: Новые школы — активные школы | B12: ='06_Сеть_и_дети'!B16 | C12: ='06_Сеть_и_дети'!C16 | D12: ='06_Сеть_и_дети'!D16 | E12: ='06_Сеть_и_дети'!E16 | F12: ='06_Сеть_и_дети'!F16 | G12: ='06_Сеть_и_дети'!G16 | H12: ='06_Сеть_и_дети'!H16 | I12: ='06_Сеть_и_дети'!I16 | ... BI12: ='06_Сеть_и_дети'!BI16
A13: Активные юрлица | B13: ='06_Сеть_и_дети'!B10 | C13: ='06_Сеть_и_дети'!C10 | D13: ='06_Сеть_и_дети'!D10 | E13: ='06_Сеть_и_дети'!E10 | F13: ='06_Сеть_и_дети'!F10 | G13: ='06_Сеть_и_дети'!G10 | H13: ='06_Сеть_и_дети'!H10 | I13: ='06_Сеть_и_дети'!I10 | ... BI13: ='06_Сеть_и_дети'!BI10
A14: Новые школы — дети | B14: ='06_Сеть_и_дети'!B24 | C14: ='06_Сеть_и_дети'!C24 | D14: ='06_Сеть_и_дети'!D24 | E14: ='06_Сеть_и_дети'!E24 | F14: ='06_Сеть_и_дети'!F24 | G14: ='06_Сеть_и_дети'!G24 | H14: ='06_Сеть_и_дети'!H24 | I14: ='06_Сеть_и_дети'!I24 | ... BI14: ='06_Сеть_и_дети'!BI24
A15: Всего активных детей | B15: ='06_Сеть_и_дети'!B25 | C15: ='06_Сеть_и_дети'!C25 | D15: ='06_Сеть_и_дети'!D25 | E15: ='06_Сеть_и_дети'!E25 | F15: ='06_Сеть_и_дети'!F25 | G15: ='06_Сеть_и_дети'!G25 | H15: ='06_Сеть_и_дети'!H25 | I15: ='06_Сеть_и_дети'!I25 | ... BI15: ='06_Сеть_и_дети'!BI25
A17: БДР — выручка
A18: Паушальные взносы, без НДС | B18: ='04_Продажи'!B26 | C18: ='04_Продажи'!C26 | D18: ='04_Продажи'!D26 | E18: ='04_Продажи'!E26 | F18: ='04_Продажи'!F26 | G18: ='04_Продажи'!G26 | H18: ='04_Продажи'!H26 | I18: ='04_Продажи'!I26 | ... BI18: ='04_Продажи'!BI26
A19: Роялти действующей сети, без НДС | B19: ='06_Сеть_и_дети'!B28/(1+'01_Вводные'!$B$58) | C19: ='06_Сеть_и_дети'!C28/(1+'01_Вводные'!$B$58) | D19: ='06_Сеть_и_дети'!D28/(1+'01_Вводные'!$B$58) | E19: ='06_Сеть_и_дети'!E28/(1+'01_Вводные'!$B$58) | F19: ='06_Сеть_и_дети'!F28/(1+'01_Вводные'!$B$58) | G19: ='06_Сеть_и_дети'!G28/(1+'01_Вводные'!$B$58) | H19: ='06_Сеть_и_дети'!H28/(1+'01_Вводные'!$B$58) | I19: ='06_Сеть_и_дети'!I28/(1+'01_Вводные'!$B$58) | ... BI19: ='06_Сеть_и_дети'!BI28/(1+'01_Вводные'!$B$58)
A20: Роялти новых школ, без НДС | B20: ='06_Сеть_и_дети'!B29/(1+'01_Вводные'!$B$58) | C20: ='06_Сеть_и_дети'!C29/(1+'01_Вводные'!$B$58) | D20: ='06_Сеть_и_дети'!D29/(1+'01_Вводные'!$B$58) | E20: ='06_Сеть_и_дети'!E29/(1+'01_Вводные'!$B$58) | F20: ='06_Сеть_и_дети'!F29/(1+'01_Вводные'!$B$58) | G20: ='06_Сеть_и_дети'!G29/(1+'01_Вводные'!$B$58) | H20: ='06_Сеть_и_дети'!H29/(1+'01_Вводные'!$B$58) | I20: ='06_Сеть_и_дети'!I29/(1+'01_Вводные'!$B$58) | ... BI20: ='06_Сеть_и_дети'!BI29/(1+'01_Вводные'!$B$58)
A21: Мерч, без НДС | B21: ='07_Мерч'!B15 | C21: ='07_Мерч'!C15 | D21: ='07_Мерч'!D15 | E21: ='07_Мерч'!E15 | F21: ='07_Мерч'!F15 | G21: ='07_Мерч'!G15 | H21: ='07_Мерч'!H15 | I21: ='07_Мерч'!I15 | ... BI21: ='07_Мерч'!BI15
A22: Лагеря, без НДС | B22: =('09_Лагеря'!B10-'09_Лагеря'!B11) | C22: =('09_Лагеря'!C10-'09_Лагеря'!C11) | D22: =('09_Лагеря'!D10-'09_Лагеря'!D11) | E22: =('09_Лагеря'!E10-'09_Лагеря'!E11) | F22: =('09_Лагеря'!F10-'09_Лагеря'!F11) | G22: =('09_Лагеря'!G10-'09_Лагеря'!G11) | H22: =('09_Лагеря'!H10-'09_Лагеря'!H11) | I22: =('09_Лагеря'!I10-'09_Лагеря'!I11) | ... BI22: =('09_Лагеря'!BI10-'09_Лагеря'!BI11)
A23: Выручка — всего, без НДС | B23: =SUM(B18:B22) | C23: =SUM(C18:C22) | D23: =SUM(D18:D22) | E23: =SUM(E18:E22) | F23: =SUM(F18:F22) | G23: =SUM(G18:G22) | H23: =SUM(H18:H22) | I23: =SUM(I18:I22) | ... BI23: =SUM(BI18:BI22)
A25: БДР — прямые расходы
A26: COGS мерча | B26: ='07_Мерч'!B16 | C26: ='07_Мерч'!C16 | D26: ='07_Мерч'!D16 | E26: ='07_Мерч'!E16 | F26: ='07_Мерч'!F16 | G26: ='07_Мерч'!G16 | H26: ='07_Мерч'!H16 | I26: ='07_Мерч'!I16 | ... BI26: ='07_Мерч'!BI16
A27: Логистика/возвраты/брак | B27: ='07_Мерч'!B17 | C27: ='07_Мерч'!C17 | D27: ='07_Мерч'!D17 | E27: ='07_Мерч'!E17 | F27: ='07_Мерч'!F17 | G27: ='07_Мерч'!G17 | H27: ='07_Мерч'!H17 | I27: ='07_Мерч'!I17 | ... BI27: ='07_Мерч'!BI17
A28: ФК — 35% прибыли мерча | B28: ='07_Мерч'!B19 | C28: ='07_Мерч'!C19 | D28: ='07_Мерч'!D19 | E28: ='07_Мерч'!E19 | F28: ='07_Мерч'!F19 | G28: ='07_Мерч'!G19 | H28: ='07_Мерч'!H19 | I28: ='07_Мерч'!I19 | ... BI28: ='07_Мерч'!BI19
A29: ФК — паушальные | B29: =B18*'01_Вводные'!$B$59 | C29: =C18*'01_Вводные'!$B$59 | D29: =D18*'01_Вводные'!$B$59 | E29: =E18*'01_Вводные'!$B$59 | F29: =F18*'01_Вводные'!$B$59 | G29: =G18*'01_Вводные'!$B$59 | H29: =H18*'01_Вводные'!$B$59 | I29: =I18*'01_Вводные'!$B$59 | ... BI29: =BI18*'01_Вводные'!$B$59
A30: ФК — роялти | B30: =(B19+B20)*'01_Вводные'!$B$60 | C30: =(C19+C20)*'01_Вводные'!$B$60 | D30: =(D19+D20)*'01_Вводные'!$B$60 | E30: =(E19+E20)*'01_Вводные'!$B$60 | F30: =(F19+F20)*'01_Вводные'!$B$60 | G30: =(G19+G20)*'01_Вводные'!$B$60 | H30: =(H19+H20)*'01_Вводные'!$B$60 | I30: =(I19+I20)*'01_Вводные'!$B$60 | ... BI30: =(BI19+BI20)*'01_Вводные'!$B$60
A31: Лагеря — расходы + партнёр | B31: ='09_Лагеря'!B12+'09_Лагеря'!B13 | C31: ='09_Лагеря'!C12+'09_Лагеря'!C13 | D31: ='09_Лагеря'!D12+'09_Лагеря'!D13 | E31: ='09_Лагеря'!E12+'09_Лагеря'!E13 | F31: ='09_Лагеря'!F12+'09_Лагеря'!F13 | G31: ='09_Лагеря'!G12+'09_Лагеря'!G13 | H31: ='09_Лагеря'!H12+'09_Лагеря'!H13 | I31: ='09_Лагеря'!I12+'09_Лагеря'!I13 | ... BI31: ='09_Лагеря'!BI12+'09_Лагеря'!BI13
A32: Прямые расходы — всего | B32: =SUM(B26:B31) | C32: =SUM(C26:C31) | D32: =SUM(D26:D31) | E32: =SUM(E26:E31) | F32: =SUM(F26:F31) | G32: =SUM(G26:G31) | H32: =SUM(H26:H31) | I32: =SUM(I26:I31) | ... BI32: =SUM(BI26:BI31)
A33: Валовая прибыль | B33: =B23-B32 | C33: =C23-C32 | D33: =D23-D32 | E33: =E23-E32 | F33: =F23-F32 | G33: =G23-G32 | H33: =H23-H32 | I33: =I23-I32 | ... BI33: =BI23-BI32
A35: БДР — OPEX
A36: ФОТ и кадровые расходы | B36: ='08_ФОТ'!B28 | C36: ='08_ФОТ'!C28 | D36: ='08_ФОТ'!D28 | E36: ='08_ФОТ'!E28 | F36: ='08_ФОТ'!F28 | G36: ='08_ФОТ'!G28 | H36: ='08_ФОТ'!H28 | I36: ='08_ФОТ'!I28 | ... BI36: ='08_ФОТ'!BI28
A37: ERP | B37: =('01_Вводные'!$B$105+(MAX(0,'06_Сеть_и_дети'!B11-'01_Вводные'!$B$106)+'06_Сеть_и_дети'!B44)*'01_Вводные'!$B$107)*'18_Календарь_тарифы'!B4 | C37: =('01_Вводные'!$B$105+(MAX(0,'06_Сеть_и_дети'!C11-'01_Вводные'!$B$106)+'06_Сеть_и_дети'!C44)*'01_Вводные'!$B$107)*'18_Календарь_тарифы'!C4 | D37: =('01_Вводные'!$B$105+(MAX(0,'06_Сеть_и_дети'!D11-'01_Вводные'!$B$106)+'06_Сеть_и_дети'!D44)*'01_Вводные'!$B$107)*'18_Календарь_тарифы'!D4 | E37: =('01_Вводные'!$B$105+(MAX(0,'06_Сеть_и_дети'!E11-'01_Вводные'!$B$106)+'06_Сеть_и_дети'!E44)*'01_Вводные'!$B$107)*'18_Календарь_тарифы'!E4 | F37: =('01_Вводные'!$B$105+(MAX(0,'06_Сеть_и_дети'!F11-'01_Вводные'!$B$106)+'06_Сеть_и_дети'!F44)*'01_Вводные'!$B$107)*'18_Календарь_тарифы'!F4 | G37: =('01_Вводные'!$B$105+(MAX(0,'06_Сеть_и_дети'!G11-'01_Вводные'!$B$106)+'06_Сеть_и_дети'!G44)*'01_Вводные'!$B$107)*'18_Календарь_тарифы'!G4 | H37: =('01_Вводные'!$B$105+(MAX(0,'06_Сеть_и_дети'!H11-'01_Вводные'!$B$106)+'06_Сеть_и_дети'!H44)*'01_Вводные'!$B$107)*'18_Календарь_тарифы'!H4 | I37: =('01_Вводные'!$B$105+(MAX(0,'06_Сеть_и_дети'!I11-'01_Вводные'!$B$106)+'06_Сеть_и_дети'!I44)*'01_Вводные'!$B$107)*'18_Календарь_тарифы'!I4 | ... BI37: =('01_Вводные'!$B$105+(MAX(0,'06_Сеть_и_дети'!BI11-'01_Вводные'!$B$106)+'06_Сеть_и_дети'!BI44)*'01_Вводные'!$B$107)*'18_Календарь_тарифы'!BI4
A38: Офис / аренда / уборка / парковка | B38: ='01_Вводные'!$B$108 | C38: ='01_Вводные'!$B$108 | D38: ='01_Вводные'!$B$108 | E38: ='01_Вводные'!$B$108 | F38: ='01_Вводные'!$B$108 | G38: ='01_Вводные'!$B$108 | H38: ='01_Вводные'!$B$108 | I38: ='01_Вводные'!$B$108 | ... BI38: ='01_Вводные'!$B$108
A39: Юристы / аудит / бухгалтерия | B39: ='01_Вводные'!$B$109*'18_Календарь_тарифы'!B4 | C39: ='01_Вводные'!$B$109*'18_Календарь_тарифы'!C4 | D39: ='01_Вводные'!$B$109*'18_Календарь_тарифы'!D4 | E39: ='01_Вводные'!$B$109*'18_Календарь_тарифы'!E4 | F39: ='01_Вводные'!$B$109*'18_Календарь_тарифы'!F4 | G39: ='01_Вводные'!$B$109*'18_Календарь_тарифы'!G4 | H39: ='01_Вводные'!$B$109*'18_Календарь_тарифы'!H4 | I39: ='01_Вводные'!$B$109*'18_Календарь_тарифы'!I4 | ... BI39: ='01_Вводные'!$B$109*'18_Календарь_тарифы'!BI4
A40: Прочие IT | B40: ='01_Вводные'!$B$110*'18_Календарь_тарифы'!B4 | C40: ='01_Вводные'!$B$110*'18_Календарь_тарифы'!C4 | D40: ='01_Вводные'!$B$110*'18_Календарь_тарифы'!D4 | E40: ='01_Вводные'!$B$110*'18_Календарь_тарифы'!E4 | F40: ='01_Вводные'!$B$110*'18_Календарь_тарифы'!F4 | G40: ='01_Вводные'!$B$110*'18_Календарь_тарифы'!G4 | H40: ='01_Вводные'!$B$110*'18_Календарь_тарифы'!H4 | I40: ='01_Вводные'!$B$110*'18_Календарь_тарифы'!I4 | ... BI40: ='01_Вводные'!$B$110*'18_Календарь_тарифы'!BI4
A41: SMM / подрядчики | B41: ='18_Календарь_тарифы'!B13 | C41: ='18_Календарь_тарифы'!C13 | D41: ='18_Календарь_тарифы'!D13 | E41: ='18_Календарь_тарифы'!E13 | F41: ='18_Календарь_тарифы'!F13 | G41: ='18_Календарь_тарифы'!G13 | H41: ='18_Календарь_тарифы'!H13 | I41: ='18_Календарь_тарифы'!I13 | ... BI41: ='18_Календарь_тарифы'!BI13
A42: Маркетинг привлечения франшиз | B42: ='04_Продажи'!B23 | C42: ='04_Продажи'!C23 | D42: ='04_Продажи'!D23 | E42: ='04_Продажи'!E23 | F42: ='04_Продажи'!F23 | G42: ='04_Продажи'!G23 | H42: ='04_Продажи'!H23 | I42: ='04_Продажи'!I23 | ... BI42: ='04_Продажи'!BI23
A43: OPEX — всего | B43: =SUM(B36:B42) | C43: =SUM(C36:C42) | D43: =SUM(D36:D42) | E43: =SUM(E36:E42) | F43: =SUM(F36:F42) | G43: =SUM(G36:G42) | H43: =SUM(H36:H42) | I43: =SUM(I36:I42) | ... BI43: =SUM(BI36:BI42)
A44: EBITDA | B44: =B33-B43 | C44: =C33-C43 | D44: =D33-D43 | E44: =E33-E43 | F44: =F33-F43 | G44: =G33-G43 | H44: =H33-H43 | I44: =I33-I43 | ... BI44: =BI33-BI43
A45: EBITDA margin | B45: =IF(B23=0,0,B44/B23) | C45: =IF(C23=0,0,C44/C23) | D45: =IF(D23=0,0,D44/D23) | E45: =IF(E23=0,0,E44/E23) | F45: =IF(F23=0,0,F44/F23) | G45: =IF(G23=0,0,G44/G23) | H45: =IF(H23=0,0,H44/H23) | I45: =IF(I23=0,0,I44/I23) | ... BI45: =IF(BI23=0,0,BI44/BI23)
...

Sheet 03_Сценарии
A1: СПАРТАК | Три сценария
A3: Сценарные множители — рабочие стресс-допущения, не утверждённый бюджет. Все суммы в млн ₽. Сценарии не зависят от выбранного варианта на дашборде.
A5: Показатель | B5: Негативный | C5: Базовый | D5: Позитивный | E5: Ед. | F5: Пояснение
A6: Выручка без НДС | B6: =SUM('19_Расчет_аналитики'!$B$717:$BI$717)/1000000 | C6: =SUM('19_Расчет_аналитики'!$B$1729:$BI$1729)/1000000 | D6: =SUM('19_Расчет_аналитики'!$B$2741:$BI$2741)/1000000 | E6: млн ₽
A7: Паушальные | B7: =SUM('19_Расчет_аналитики'!$B$712:$BI$712)/1000000 | C7: =SUM('19_Расчет_аналитики'!$B$1724:$BI$1724)/1000000 | D7: =SUM('19_Расчет_аналитики'!$B$2736:$BI$2736)/1000000 | E7: млн ₽
A8: Роялти | B8: =SUM('19_Расчет_аналитики'!$B$713:$BI$713,'19_Расчет_аналитики'!$B$714:$BI$714)/1000000 | C8: =SUM('19_Расчет_аналитики'!$B$1725:$BI$1725,'19_Расчет_аналитики'!$B$1726:$BI$1726)/1000000 | D8: =SUM('19_Расчет_аналитики'!$B$2737:$BI$2737,'19_Расчет_аналитики'!$B$2738:$BI$2738)/1000000 | E8: млн ₽
A9: Мерч | B9: =SUM('19_Расчет_аналитики'!$B$715:$BI$715)/1000000 | C9: =SUM('19_Расчет_аналитики'!$B$1727:$BI$1727)/1000000 | D9: =SUM('19_Расчет_аналитики'!$B$2739:$BI$2739)/1000000 | E9: млн ₽
A10: Лагеря | B10: =SUM('19_Расчет_аналитики'!$B$716:$BI$716)/1000000 | C10: =SUM('19_Расчет_аналитики'!$B$1728:$BI$1728)/1000000 | D10: =SUM('19_Расчет_аналитики'!$B$2740:$BI$2740)/1000000 | E10: млн ₽
A11: EBITDA | B11: =SUM('19_Расчет_аналитики'!$B$738:$BI$738)/1000000 | C11: =SUM('19_Расчет_аналитики'!$B$1750:$BI$1750)/1000000 | D11: =SUM('19_Расчет_аналитики'!$B$2762:$BI$2762)/1000000 | E11: млн ₽
A12: Рентабельность EBITDA | B12: =IF(SUM('19_Расчет_аналитики'!$B$717:$BI$717)=0,0,SUM('19_Расчет_аналитики'!$B$738:$BI$738)/SUM('19_Расчет_аналитики'!$B$717:$BI$717)) | C12: =IF(SUM('19_Расчет_аналитики'!$B$1729:$BI$1729)=0,0,SUM('19_Расчет_аналитики'!$B$1750:$BI$1750)/SUM('19_Расчет_аналитики'!$B$1729:$BI$1729)) | D12: =IF(SUM('19_Расчет_аналитики'!$B$2741:$BI$2741)=0,0,SUM('19_Расчет_аналитики'!$B$2762:$BI$2762)/SUM('19_Расчет_аналитики'!$B$2741:$BI$2741)) | E12: %
A13: Поток после CAPEX, до займа | B13: =SUM('19_Расчет_аналитики'!$B$762:$BI$762)/1000000 | C13: =SUM('19_Расчет_аналитики'!$B$1774:$BI$1774)/1000000 | D13: =SUM('19_Расчет_аналитики'!$B$2786:$BI$2786)/1000000 | E13: млн ₽
A14: Возврат займа ФК | B14: =SUM('19_Расчет_аналитики'!$B$764:$BI$764)/1000000 | C14: =SUM('19_Расчет_аналитики'!$B$1776:$BI$1776)/1000000 | D14: =SUM('19_Расчет_аналитики'!$B$2788:$BI$2788)/1000000 | E14: млн ₽
A15: Поток после займа | B15: =SUM('19_Расчет_аналитики'!$B$765:$BI$765)/1000000 | C15: =SUM('19_Расчет_аналитики'!$B$1777:$BI$1777)/1000000 | D15: =SUM('19_Расчет_аналитики'!$B$2789:$BI$2789)/1000000 | E15: млн ₽
A16: Деньги на конец | B16: ='19_Расчет_аналитики'!$BI$766/1000000 | C16: ='19_Расчет_аналитики'!$BI$1778/1000000 | D16: ='19_Расчет_аналитики'!$BI$2790/1000000 | E16: млн ₽
A17: Пиковый кассовый дефицит | B17: =MAX(0,-MIN('19_Расчет_аналитики'!$B$766:$BI$766))/1000000 | C17: =MAX(0,-MIN('19_Расчет_аналитики'!$B$1778:$BI$1778))/1000000 | D17: =MAX(0,-MIN('19_Расчет_аналитики'!$B$2790:$BI$2790))/1000000 | E17: млн ₽ | F17: Не оформленный кредит: сумма минимального отрицательного остатка. Проценты на допфинансирование не добавлены.
A18: Закупки товара | B18: =SUM('19_Расчет_аналитики'!$B$626:$BI$626)/1000000 | C18: =SUM('19_Расчет_аналитики'!$B$1638:$BI$1638)/1000000 | D18: =SUM('19_Расчет_аналитики'!$B$2650:$BI$2650)/1000000 | E18: млн ₽
A19: Пик товарного остатка | B19: =MAX('19_Расчет_аналитики'!$B$627:$BI$627)/1000000 | C19: =MAX('19_Расчет_аналитики'!$B$1639:$BI$1639)/1000000 | D19: =MAX('19_Расчет_аналитики'!$B$2651:$BI$2651)/1000000 | E19: млн ₽
A20: Склад на конец | B20: ='19_Расчет_аналитики'!$BI$770/1000000 | C20: ='19_Расчет_аналитики'!$BI$1782/1000000 | D20: ='19_Расчет_аналитики'!$BI$2794/1000000 | E20: млн ₽
A21: Займ на конец | B21: ='19_Расчет_аналитики'!$BI$769/1000000 | C21: ='19_Расчет_аналитики'!$BI$1781/1000000 | D21: ='19_Расчет_аналитики'!$BI$2793/1000000 | E21: млн ₽
A22: Нехватка товара (по себестоимости) | B22: =MAX('19_Расчет_аналитики'!$B$628:$BI$628)/1000000 | C22: =MAX('19_Расчет_аналитики'!$B$1640:$BI$1640)/1000000 | D22: =MAX('19_Расчет_аналитики'!$B$2652:$BI$2652)/1000000 | E22: млн ₽ | F22: Если >0, выручка плана не обеспечена запасом: нужны другие сроки/объёмы закупок.
A23: Продано франшиз | B23: =SUM('19_Расчет_аналитики'!$B$338:$BI$338) | C23: =SUM('19_Расчет_аналитики'!$B$1350:$BI$1350) | D23: =SUM('19_Расчет_аналитики'!$B$2362:$BI$2362) | E23: шт.
A24: Открыто школ | B24: =SUM('19_Расчет_аналитики'!$B$341:$BI$341) | C24: =SUM('19_Расчет_аналитики'!$B$1353:$BI$1353) | D24: =SUM('19_Расчет_аналитики'!$B$2365:$BI$2365) | E24: шт.
A25: Активные школы на конец | B25: ='19_Расчет_аналитики'!$BI$372 | C25: ='19_Расчет_аналитики'!$BI$1384 | D25: ='19_Расчет_аналитики'!$BI$2396 | E25: шт.
A26: Среднее активных детей в месяц | B26: =AVERAGE('19_Расчет_аналитики'!$B$380:$BI$380) | C26: =AVERAGE('19_Расчет_аналитики'!$B$1392:$BI$1392) | D26: =AVERAGE('19_Расчет_аналитики'!$B$2404:$BI$2404) | E26: чел.
A27: Операционные выплаты ФК, деньги | B27: =SUM('19_Расчет_аналитики'!$B$755:$BI$755)/1000000 | C27: =SUM('19_Расчет_аналитики'!$B$1767:$BI$1767)/1000000 | D27: =SUM('19_Расчет_аналитики'!$B$2779:$BI$2779)/1000000 | E27: млн ₽
A28: CAPEX — всего | B28: =SUM('19_Расчет_аналитики'!$B$751:$BI$751)/1000000 | C28: =SUM('19_Расчет_аналитики'!$B$1763:$BI$1763)/1000000 | D28: =SUM('19_Расчет_аналитики'!$B$2775:$BI$2775)/1000000 | E28: млн ₽
A30: EBITDA по сезонам, млн ₽
A31: 2026/27 | B31: =SUM('19_Расчет_аналитики'!$B$738:$M$738)/1000000 | C31: =SUM('19_Расчет_аналитики'!$B$1750:$M$1750)/1000000 | D31: =SUM('19_Расчет_аналитики'!$B$2762:$M$2762)/1000000
A32: 2027/28 | B32: =SUM('19_Расчет_аналитики'!$N$738:$Y$738)/1000000 | C32: =SUM('19_Расчет_аналитики'!$N$1750:$Y$1750)/1000000 | D32: =SUM('19_Расчет_аналитики'!$N$2762:$Y$2762)/1000000
A33: 2028/29 | B33: =SUM('19_Расчет_аналитики'!$Z$738:$AK$738)/1000000 | C33: =SUM('19_Расчет_аналитики'!$Z$1750:$AK$1750)/1000000 | D33: =SUM('19_Расчет_аналитики'!$Z$2762:$AK$2762)/1000000
A34: 2029/30 | B34: =SUM('19_Расчет_аналитики'!$AL$738:$AW$738)/1000000 | C34: =SUM('19_Расчет_аналитики'!$AL$1750:$AW$1750)/1000000 | D34: =SUM('19_Расчет_аналитики'!$AL$2762:$AW$2762)/1000000
A35: 2030/31 | B35: =SUM('19_Расчет_аналитики'!$AX$738:$BI$738)/1000000 | C35: =SUM('19_Расчет_аналитики'!$AX$1750:$BI$1750)/1000000 | D35: =SUM('19_Расчет_аналитики'!$AX$2762:$BI$2762)/1000000

Sheet 04_Продажи
A1: Продажи франшиз, лиды и маркетинг
A3: Контроль сезонных планов
A4: Сезон | B4: Годовой план | C4: Сумма весов | D4: Расчёт продаж | E4: Отклонение
A5: 1 | B5: ='01_Вводные'!B36 | C5: ='01_Вводные'!O36 | D5: =SUM(B15:M15) | E5: =ROUND(D5-B5,8)
A6: 2 | B6: ='01_Вводные'!B37 | C6: ='01_Вводные'!O37 | D6: =SUM(N15:Y15) | E6: =ROUND(D6-B6,8)
A7: 3 | B7: ='01_Вводные'!B38 | C7: ='01_Вводные'!O38 | D7: =SUM(Z15:AK15) | E7: =ROUND(D7-B7,8)
A8: 4 | B8: ='01_Вводные'!B39 | C8: ='01_Вводные'!O39 | D8: =SUM(AL15:AW15) | E8: =ROUND(D8-B8,8)
A9: 5 | B9: ='01_Вводные'!B40 | C9: ='01_Вводные'!O40 | D9: =SUM(AX15:BI15) | E9: =ROUND(D9-B9,8)
A10: Помесячный план
B11: =DATE(YEAR('01_Вводные'!$B$7),MONTH('01_Вводные'!$B$7)+0,1) | C11: =DATE(YEAR('01_Вводные'!$B$7),MONTH('01_Вводные'!$B$7)+1,1) | D11: =DATE(YEAR('01_Вводные'!$B$7),MONTH('01_Вводные'!$B$7)+2,1) | E11: =DATE(YEAR('01_Вводные'!$B$7),MONTH('01_Вводные'!$B$7)+3,1) | F11: =DATE(YEAR('01_Вводные'!$B$7),MONTH('01_Вводные'!$B$7)+4,1) | G11: =DATE(YEAR('01_Вводные'!$B$7),MONTH('01_Вводные'!$B$7)+5,1) | H11: =DATE(YEAR('01_Вводные'!$B$7),MONTH('01_Вводные'!$B$7)+6,1) | I11: =DATE(YEAR('01_Вводные'!$B$7),MONTH('01_Вводные'!$B$7)+7,1) | J11: =DATE(YEAR('01_Вводные'!$B$7),MONTH('01_Вводные'!$B$7)+8,1) | K11: =DATE(YEAR('01_Вводные'!$B$7),MONTH('01_Вводные'!$B$7)+9,1) | L11: =DATE(YEAR('01_Вводные'!$B$7),MONTH('01_Вводные'!$B$7)+10,1) | M11: =DATE(YEAR('01_Вводные'!$B$7),MONTH('01_Вводные'!$B$7)+11,1) | N11: =DATE(YEAR('01_Вводные'!$B$7),MONTH('01_Вводные'!$B$7)+12,1) | O11: =DATE(YEAR('01_Вводные'!$B$7),MONTH('01_Вводные'!$B$7)+13,1) | P11: =DATE(YEAR('01_Вводные'!$B$7),MONTH('01_Вводные'!$B$7)+14,1) | Q11: =DATE(YEAR('01_Вводные'!$B$7),MONTH('01_Вводные'!$B$7)+15,1) | R11: =DATE(YEAR('01_Вводные'!$B$7),MONTH('01_Вводные'!$B$7)+16,1) | S11: =DATE(YEAR('01_Вводные'!$B$7),MONTH('01_Вводные'!$B$7)+17,1) | T11: =DATE(YEAR('01_Вводные'!$B$7),MONTH('01_Вводные'!$B$7)+18,1) | U11: =DATE(YEAR('01_Вводные'!$B$7),MONTH('01_Вводные'!$B$7)+19,1) | V11: =DATE(YEAR('01_Вводные'!$B$7),MONTH('01_Вводные'!$B$7)+20,1) | W11: =DATE(YEAR('01_Вводные'!$B$7),MONTH('01_Вводные'!$B$7)+21,1) | X11: =DATE(YEAR('01_Вводные'!$B$7),MONTH('01_Вводные'!$B$7)+22,1) | Y11: =DATE(YEAR('01_Вводные'!$B$7),MONTH('01_Вводные'!$B$7)+23,1) | Z11: =DATE(YEAR('01_Вводные'!$B$7),MONTH('01_Вводные'!$B$7)+24,1) | AA11: =DATE(YEAR('01_Вводные'!$B$7),MONTH('01_Вводные'!$B$7)+25,1) | AB11: =DATE(YEAR('01_Вводные'!$B$7),MONTH('01_Вводные'!$B$7)+26,1) | AC11: =DATE(YEAR('01_Вводные'!$B$7),MONTH('01_Вводные'!$B$7)+27,1) | AD11: =DATE(YEAR('01_Вводные'!$B$7),MONTH('01_Вводные'!$B$7)+28,1) | AE11: =DATE(YEAR('01_Вводные'!$B$7),MONTH('01_Вводные'!$B$7)+29,1) | AF11: =DATE(YEAR('01_Вводные'!$B$7),MONTH('01_Вводные'!$B$7)+30,1) | AG11: =DATE(YEAR('01_Вводные'!$B$7),MONTH('01_Вводные'!$B$7)+31,1) | AH11: =DATE(YEAR('01_Вводные'!$B$7),MONTH('01_Вводные'!$B$7)+32,1) | AI11: =DATE(YEAR('01_Вводные'!$B$7),MONTH('01_Вводные'!$B$7)+33,1) | AJ11: =DATE(YEAR('01_Вводные'!$B$7),MONTH('01_Вводные'!$B$7)+34,1) | AK11: =DATE(YEAR('01_Вводные'!$B$7),MONTH('01_Вводные'!$B$7)+35,1) | AL11: =DATE(YEAR('01_Вводные'!$B$7),MONTH('01_Вводные'!$B$7)+36,1) | AM11: =DATE(YEAR('01_Вводные'!$B$7),MONTH('01_Вводные'!$B$7)+37,1) | AN11: =DATE(YEAR('01_Вводные'!$B$7),MONTH('01_Вводные'!$B$7)+38,1) | AO11: =DATE(YEAR('01_Вводные'!$B$7),MONTH('01_Вводные'!$B$7)+39,1) | AP11: =DATE(YEAR('01_Вводные'!$B$7),MONTH('01_Вводные'!$B$7)+40,1) | AQ11: =DATE(YEAR('01_Вводные'!$B$7),MONTH('01_Вводные'!$B$7)+41,1) | AR11: =DATE(YEAR('01_Вводные'!$B$7),MONTH('01_Вводные'!$B$7)+42,1) | AS11: =DATE(YEAR('01_Вводные'!$B$7),MONTH('01_Вводные'!$B$7)+43,1) | AT11: =DATE(YEAR('01_Вводные'!$B$7),MONTH('01_Вводные'!$B$7)+44,1) | AU11: =DATE(YEAR('01_Вводные'!$B$7),MONTH('01_Вводные'!$B$7)+45,1) | AV11: =DATE(YEAR('01_Вводные'!$B$7),MONTH('01_Вводные'!$B$7)+46,1) | AW11: =DATE(YEAR('01_Вводные'!$B$7),MONTH('01_Вводные'!$B$7)+47,1) | AX11: =DATE(YEAR('01_Вводные'!$B$7),MONTH('01_Вводные'!$B$7)+48,1) | AY11: =DATE(YEAR('01_Вводные'!$B$7),MONTH('01_Вводные'!$B$7)+49,1) | AZ11: =DATE(YEAR('01_Вводные'!$B$7),MONTH('01_Вводные'!$B$7)+50,1) | BA11: =DATE(YEAR('01_Вводные'!$B$7),MONTH('01_Вводные'!$B$7)+51,1) | BB11: =DATE(YEAR('01_Вводные'!$B$7),MONTH('01_Вводные'!$B$7)+52,1) | BC11: =DATE(YEAR('01_Вводные'!$B$7),MONTH('01_Вводные'!$B$7)+53,1) | BD11: =DATE(YEAR('01_Вводные'!$B$7),MONTH('01_Вводные'!$B$7)+54,1) | BE11: =DATE(YEAR('01_Вводные'!$B$7),MONTH('01_Вводные'!$B$7)+55,1) | BF11: =DATE(YEAR('01_Вводные'!$B$7),MONTH('01_Вводные'!$B$7)+56,1) | BG11: =DATE(YEAR('01_Вводные'!$B$7),MONTH('01_Вводные'!$B$7)+57,1) | BH11: =DATE(YEAR('01_Вводные'!$B$7),MONTH('01_Вводные'!$B$7)+58,1) | BI11: =DATE(YEAR('01_Вводные'!$B$7),MONTH('01_Вводные'!$B$7)+59,1)
A12: Сезон | B12: =INT((0)/12)+1 | C12: =INT((1)/12)+1 | D12: =INT((2)/12)+1 | E12: =INT((3)/12)+1 | F12: =INT((4)/12)+1 | G12: =INT((5)/12)+1 | H12: =INT((6)/12)+1 | I12: =INT((7)/12)+1 | J12: =INT((8)/12)+1 | K12: =INT((9)/12)+1 | L12: =INT((10)/12)+1 | M12: =INT((11)/12)+1 | N12: =INT((12)/12)+1 | O12: =INT((13)/12)+1 | P12: =INT((14)/12)+1 | Q12: =INT((15)/12)+1 | R12: =INT((16)/12)+1 | S12: =INT((17)/12)+1 | T12: =INT((18)/12)+1 | U12: =INT((19)/12)+1 | V12: =INT((20)/12)+1 | W12: =INT((21)/12)+1 | X12: =INT((22)/12)+1 | Y12: =INT((23)/12)+1 | Z12: =INT((24)/12)+1 | AA12: =INT((25)/12)+1 | AB12: =INT((26)/12)+1 | AC12: =INT((27)/12)+1 | AD12: =INT((28)/12)+1 | AE12: =INT((29)/12)+1 | AF12: =INT((30)/12)+1 | AG12: =INT((31)/12)+1 | AH12: =INT((32)/12)+1 | AI12: =INT((33)/12)+1 | AJ12: =INT((34)/12)+1 | AK12: =INT((35)/12)+1 | AL12: =INT((36)/12)+1 | AM12: =INT((37)/12)+1 | AN12: =INT((38)/12)+1 | AO12: =INT((39)/12)+1 | AP12: =INT((40)/12)+1 | AQ12: =INT((41)/12)+1 | AR12: =INT((42)/12)+1 | AS12: =INT((43)/12)+1 | AT12: =INT((44)/12)+1 | AU12: =INT((45)/12)+1 | AV12: =INT((46)/12)+1 | AW12: =INT((47)/12)+1 | AX12: =INT((48)/12)+1 | AY12: =INT((49)/12)+1 | AZ12: =INT((50)/12)+1 | BA12: =INT((51)/12)+1 | BB12: =INT((52)/12)+1 | BC12: =INT((53)/12)+1 | BD12: =INT((54)/12)+1 | BE12: =INT((55)/12)+1 | BF12: =INT((56)/12)+1 | BG12: =INT((57)/12)+1 | BH12: =INT((58)/12)+1 | BI12: =INT((59)/12)+1
A13: Месяц сезона | B13: 1 | C13: 2 | D13: 3 | E13: 4 | F13: 5 | G13: 6 | H13: 7 | I13: 8 | J13: 9 | K13: 10 | L13: 11 | M13: 12 | N13: 1 | O13: 2 | P13: 3 | Q13: 4 | R13: 5 | S13: 6 | T13: 7 | U13: 8 | V13: 9 | W13: 10 | X13: 11 | Y13: 12 | Z13: 1 | AA13: 2 | AB13: 3 | AC13: 4 | AD13: 5 | AE13: 6 | AF13: 7 | AG13: 8 | AH13: 9 | AI13: 10 | AJ13: 11 | AK13: 12 | AL13: 1 | AM13: 2 | AN13: 3 | AO13: 4 | AP13: 5 | AQ13: 6 | AR13: 7 | AS13: 8 | AT13: 9 | AU13: 10 | AV13: 11 | AW13: 12 | AX13: 1 | AY13: 2 | AZ13: 3 | BA13: 4 | BB13: 5 | BC13: 6 | BD13: 7 | BE13: 8 | BF13: 9 | BG13: 10 | BH13: 11 | BI13: 12
A15: Продажи франшиз — финансовый план | B15: =0 | C15: ='01_Вводные'!$B$36*INDEX('01_Вводные'!$C$36:$N$36,1,MOD(MONTH(C$11)-9,12)+1)/(SUM('01_Вводные'!$C$36:$N$36)-INDEX('01_Вводные'!$C$36:$N$36,1,MOD(MONTH('01_Вводные'!$B$7)-9,12)+1)) | D15: ='01_Вводные'!$B$36*INDEX('01_Вводные'!$C$36:$N$36,1,MOD(MONTH(D$11)-9,12)+1)/(SUM('01_Вводные'!$C$36:$N$36)-INDEX('01_Вводные'!$C$36:$N$36,1,MOD(MONTH('01_Вводные'!$B$7)-9,12)+1)) | E15: ='01_Вводные'!$B$36*INDEX('01_Вводные'!$C$36:$N$36,1,MOD(MONTH(E$11)-9,12)+1)/(SUM('01_Вводные'!$C$36:$N$36)-INDEX('01_Вводные'!$C$36:$N$36,1,MOD(MONTH('01_Вводные'!$B$7)-9,12)+1)) | F15: ='01_Вводные'!$B$36*INDEX('01_Вводные'!$C$36:$N$36,1,MOD(MONTH(F$11)-9,12)+1)/(SUM('01_Вводные'!$C$36:$N$36)-INDEX('01_Вводные'!$C$36:$N$36,1,MOD(MONTH('01_Вводные'!$B$7)-9,12)+1)) | G15: ='01_Вводные'!$B$36*INDEX('01_Вводные'!$C$36:$N$36,1,MOD(MONTH(G$11)-9,12)+1)/(SUM('01_Вводные'!$C$36:$N$36)-INDEX('01_Вводные'!$C$36:$N$36,1,MOD(MONTH('01_Вводные'!$B$7)-9,12)+1)) | H15: ='01_Вводные'!$B$36*INDEX('01_Вводные'!$C$36:$N$36,1,MOD(MONTH(H$11)-9,12)+1)/(SUM('01_Вводные'!$C$36:$N$36)-INDEX('01_Вводные'!$C$36:$N$36,1,MOD(MONTH('01_Вводные'!$B$7)-9,12)+1)) | I15: ='01_Вводные'!$B$36*INDEX('01_Вводные'!$C$36:$N$36,1,MOD(MONTH(I$11)-9,12)+1)/(SUM('01_Вводные'!$C$36:$N$36)-INDEX('01_Вводные'!$C$36:$N$36,1,MOD(MONTH('01_Вводные'!$B$7)-9,12)+1)) | J15: ='01_Вводные'!$B$36*INDEX('01_Вводные'!$C$36:$N$36,1,MOD(MONTH(J$11)-9,12)+1)/(SUM('01_Вводные'!$C$36:$N$36)-INDEX('01_Вводные'!$C$36:$N$36,1,MOD(MONTH('01_Вводные'!$B$7)-9,12)+1)) | ... M15: ='01_Вводные'!$B$36*INDEX('01_Вводные'!$C$36:$N$36,1,MOD(MONTH(M$11)-9,12)+1)/(SUM('01_Вводные'!$C$36:$N$36)-INDEX('01_Вводные'!$C$36:$N$36,1,MOD(MONTH('01_Вводные'!$B$7)-9,12)+1)) | N15: ='01_Вводные'!$B$37*INDEX('01_Вводные'!$C$37:$N$37,1,MOD(MONTH(N$11)-9,12)+1)/SUM('01_Вводные'!$C$37:$N$37) | O15: ='01_Вводные'!$B$37*INDEX('01_Вводные'!$C$37:$N$37,1,MOD(MONTH(O$11)-9,12)+1)/SUM('01_Вводные'!$C$37:$N$37) | P15: ='01_Вводные'!$B$37*INDEX('01_Вводные'!$C$37:$N$37,1,MOD(MONTH(P$11)-9,12)+1)/SUM('01_Вводные'!$C$37:$N$37) | Q15: ='01_Вводные'!$B$37*INDEX('01_Вводные'!$C$37:$N$37,1,MOD(MONTH(Q$11)-9,12)+1)/SUM('01_Вводные'!$C$37:$N$37) | R15: ='01_Вводные'!$B$37*INDEX('01_Вводные'!$C$37:$N$37,1,MOD(MONTH(R$11)-9,12)+1)/SUM('01_Вводные'!$C$37:$N$37) | S15: ='01_Вводные'!$B$37*INDEX('01_Вводные'!$C$37:$N$37,1,MOD(MONTH(S$11)-9,12)+1)/SUM('01_Вводные'!$C$37:$N$37) | T15: ='01_Вводные'!$B$37*INDEX('01_Вводные'!$C$37:$N$37,1,MOD(MONTH(T$11)-9,12)+1)/SUM('01_Вводные'!$C$37:$N$37) | U15: ='01_Вводные'!$B$37*INDEX('01_Вводные'!$C$37:$N$37,1,MOD(MONTH(U$11)-9,12)+1)/SUM('01_Вводные'!$C$37:$N$37) | ... Y15: ='01_Вводные'!$B$37*INDEX('01_Вводные'!$C$37:$N$37,1,MOD(MONTH(Y$11)-9,12)+1)/SUM('01_Вводные'!$C$37:$N$37) | Z15: ='01_Вводные'!$B$38*INDEX('01_Вводные'!$C$38:$N$38,1,MOD(MONTH(Z$11)-9,12)+1)/SUM('01_Вводные'!$C$38:$N$38) | AA15: ='01_Вводные'!$B$38*INDEX('01_Вводные'!$C$38:$N$38,1,MOD(MONTH(AA$11)-9,12)+1)/SUM('01_Вводные'!$C$38:$N$38) | AB15: ='01_Вводные'!$B$38*INDEX('01_Вводные'!$C$38:$N$38,1,MOD(MONTH(AB$11)-9,12)+1)/SUM('01_Вводные'!$C$38:$N$38) | AC15: ='01_Вводные'!$B$38*INDEX('01_Вводные'!$C$38:$N$38,1,MOD(MONTH(AC$11)-9,12)+1)/SUM('01_Вводные'!$C$38:$N$38) | AD15: ='01_Вводные'!$B$38*INDEX('01_Вводные'!$C$38:$N$38,1,MOD(MONTH(AD$11)-9,12)+1)/SUM('01_Вводные'!$C$38:$N$38) | AE15: ='01_Вводные'!$B$38*INDEX('01_Вводные'!$C$38:$N$38,1,MOD(MONTH(AE$11)-9,12)+1)/SUM('01_Вводные'!$C$38:$N$38) | AF15: ='01_Вводные'!$B$38*INDEX('01_Вводные'!$C$38:$N$38,1,MOD(MONTH(AF$11)-9,12)+1)/SUM('01_Вводные'!$C$38:$N$38) | AG15: ='01_Вводные'!$B$38*INDEX('01_Вводные'!$C$38:$N$38,1,MOD(MONTH(AG$11)-9,12)+1)/SUM('01_Вводные'!$C$38:$N$38) | ... AK15: ='01_Вводные'!$B$38*INDEX('01_Вводные'!$C$38:$N$38,1,MOD(MONTH(AK$11)-9,12)+1)/SUM('01_Вводные'!$C$38:$N$38) | AL15: ='01_Вводные'!$B$39*INDEX('01_Вводные'!$C$39:$N$39,1,MOD(MONTH(AL$11)-9,12)+1)/SUM('01_Вводные'!$C$39:$N$39) | AM15: ='01_Вводные'!$B$39*INDEX('01_Вводные'!$C$39:$N$39,1,MOD(MONTH(AM$11)-9,12)+1)/SUM('01_Вводные'!$C$39:$N$39) | AN15: ='01_Вводные'!$B$39*INDEX('01_Вводные'!$C$39:$N$39,1,MOD(MONTH(AN$11)-9,12)+1)/SUM('01_Вводные'!$C$39:$N$39) | AO15: ='01_Вводные'!$B$39*INDEX('01_Вводные'!$C$39:$N$39,1,MOD(MONTH(AO$11)-9,12)+1)/SUM('01_Вводные'!$C$39:$N$39) | AP15: ='01_Вводные'!$B$39*INDEX('01_Вводные'!$C$39:$N$39,1,MOD(MONTH(AP$11)-9,12)+1)/SUM('01_Вводные'!$C$39:$N$39) | AQ15: ='01_Вводные'!$B$39*INDEX('01_Вводные'!$C$39:$N$39,1,MOD(MONTH(AQ$11)-9,12)+1)/SUM('01_Вводные'!$C$39:$N$39) | AR15: ='01_Вводные'!$B$39*INDEX('01_Вводные'!$C$39:$N$39,1,MOD(MONTH(AR$11)-9,12)+1)/SUM('01_Вводные'!$C$39:$N$39) | AS15: ='01_Вводные'!$B$39*INDEX('01_Вводные'!$C$39:$N$39,1,MOD(MONTH(AS$11)-9,12)+1)/SUM('01_Вводные'!$C$39:$N$39) | ... AW15: ='01_Вводные'!$B$39*INDEX('01_Вводные'!$C$39:$N$39,1,MOD(MONTH(AW$11)-9,12)+1)/SUM('01_Вводные'!$C$39:$N$39) | AX15: ='01_Вводные'!$B$40*INDEX('01_Вводные'!$C$40:$N$40,1,MOD(MONTH(AX$11)-9,12)+1)/SUM('01_Вводные'!$C$40:$N$40) | AY15: ='01_Вводные'!$B$40*INDEX('01_Вводные'!$C$40:$N$40,1,MOD(MONTH(AY$11)-9,12)+1)/SUM('01_Вводные'!$C$40:$N$40) | AZ15: ='01_Вводные'!$B$40*INDEX('01_Вводные'!$C$40:$N$40,1,MOD(MONTH(AZ$11)-9,12)+1)/SUM('01_Вводные'!$C$40:$N$40) | BA15: ='01_Вводные'!$B$40*INDEX('01_Вводные'!$C$40:$N$40,1,MOD(MONTH(BA$11)-9,12)+1)/SUM('01_Вводные'!$C$40:$N$40) | BB15: ='01_Вводные'!$B$40*INDEX('01_Вводные'!$C$40:$N$40,1,MOD(MONTH(BB$11)-9,12)+1)/SUM('01_Вводные'!$C$40:$N$40) | BC15: ='01_Вводные'!$B$40*INDEX('01_Вводные'!$C$40:$N$40,1,MOD(MONTH(BC$11)-9,12)+1)/SUM('01_Вводные'!$C$40:$N$40) | BD15: ='01_Вводные'!$B$40*INDEX('01_Вводные'!$C$40:$N$40,1,MOD(MONTH(BD$11)-9,12)+1)/SUM('01_Вводные'!$C$40:$N$40) | BE15: ='01_Вводные'!$B$40*INDEX('01_Вводные'!$C$40:$N$40,1,MOD(MONTH(BE$11)-9,12)+1)/SUM('01_Вводные'!$C$40:$N$40) | ... BI15: ='01_Вводные'!$B$40*INDEX('01_Вводные'!$C$40:$N$40,1,MOD(MONTH(BI$11)-9,12)+1)/SUM('01_Вводные'!$C$40:$N$40)
A16: Операционный ориентир, целые | B16: =ROUND(B15,0) | C16: =ROUND(SUM($B15:C15),0)-ROUND(SUM($B15:B15),0) | D16: =ROUND(SUM($B15:D15),0)-ROUND(SUM($B15:C15),0) | E16: =ROUND(SUM($B15:E15),0)-ROUND(SUM($B15:D15),0) | F16: =ROUND(SUM($B15:F15),0)-ROUND(SUM($B15:E15),0) | G16: =ROUND(SUM($B15:G15),0)-ROUND(SUM($B15:F15),0) | H16: =ROUND(SUM($B15:H15),0)-ROUND(SUM($B15:G15),0) | I16: =ROUND(SUM($B15:I15),0)-ROUND(SUM($B15:H15),0) | J16: =ROUND(SUM($B15:J15),0)-ROUND(SUM($B15:I15),0) | ... M16: =ROUND(SUM($B15:M15),0)-ROUND(SUM($B15:L15),0) | N16: =ROUND(N15,0) | O16: =ROUND(SUM($N15:O15),0)-ROUND(SUM($N15:N15),0) | P16: =ROUND(SUM($N15:P15),0)-ROUND(SUM($N15:O15),0) | Q16: =ROUND(SUM($N15:Q15),0)-ROUND(SUM($N15:P15),0) | R16: =ROUND(SUM($N15:R15),0)-ROUND(SUM($N15:Q15),0) | S16: =ROUND(SUM($N15:S15),0)-ROUND(SUM($N15:R15),0) | T16: =ROUND(SUM($N15:T15),0)-ROUND(SUM($N15:S15),0) | U16: =ROUND(SUM($N15:U15),0)-ROUND(SUM($N15:T15),0) | V16: =ROUND(SUM($N15:V15),0)-ROUND(SUM($N15:U15),0) | ... Y16: =ROUND(SUM($N15:Y15),0)-ROUND(SUM($N15:X15),0) | Z16: =ROUND(Z15,0) | AA16: =ROUND(SUM($Z15:AA15),0)-ROUND(SUM($Z15:Z15),0) | AB16: =ROUND(SUM($Z15:AB15),0)-ROUND(SUM($Z15:AA15),0) | AC16: =ROUND(SUM($Z15:AC15),0)-ROUND(SUM($Z15:AB15),0) | AD16: =ROUND(SUM($Z15:AD15),0)-ROUND(SUM($Z15:AC15),0) | AE16: =ROUND(SUM($Z15:AE15),0)-ROUND(SUM($Z15:AD15),0) | AF16: =ROUND(SUM($Z15:AF15),0)-ROUND(SUM($Z15:AE15),0) | AG16: =ROUND(SUM($Z15:AG15),0)-ROUND(SUM($Z15:AF15),0) | AH16: =ROUND(SUM($Z15:AH15),0)-ROUND(SUM($Z15:AG15),0) | ... AK16: =ROUND(SUM($Z15:AK15),0)-ROUND(SUM($Z15:AJ15),0) | AL16: =ROUND(AL15,0) | AM16: =ROUND(SUM($AL15:AM15),0)-ROUND(SUM($AL15:AL15),0) | AN16: =ROUND(SUM($AL15:AN15),0)-ROUND(SUM($AL15:AM15),0) | AO16: =ROUND(SUM($AL15:AO15),0)-ROUND(SUM($AL15:AN15),0) | AP16: =ROUND(SUM($AL15:AP15),0)-ROUND(SUM($AL15:AO15),0) | AQ16: =ROUND(SUM($AL15:AQ15),0)-ROUND(SUM($AL15:AP15),0) | AR16: =ROUND(SUM($AL15:AR15),0)-ROUND(SUM($AL15:AQ15),0) | AS16: =ROUND(SUM($AL15:AS15),0)-ROUND(SUM($AL15:AR15),0) | AT16: =ROUND(SUM($AL15:AT15),0)-ROUND(SUM($AL15:AS15),0) | ... AW16: =ROUND(SUM($AL15:AW15),0)-ROUND(SUM($AL15:AV15),0) | AX16: =ROUND(AX15,0) | AY16: =ROUND(SUM($AX15:AY15),0)-ROUND(SUM($AX15:AX15),0) | AZ16: =ROUND(SUM($AX15:AZ15),0)-ROUND(SUM($AX15:AY15),0) | BA16: =ROUND(SUM($AX15:BA15),0)-ROUND(SUM($AX15:AZ15),0) | BB16: =ROUND(SUM($AX15:BB15),0)-ROUND(SUM($AX15:BA15),0) | BC16: =ROUND(SUM($AX15:BC15),0)-ROUND(SUM($AX15:BB15),0) | BD16: =ROUND(SUM($AX15:BD15),0)-ROUND(SUM($AX15:BC15),0) | BE16: =ROUND(SUM($AX15:BE15),0)-ROUND(SUM($AX15:BD15),0) | BF16: =ROUND(SUM($AX15:BF15),0)-ROUND(SUM($AX15:BE15),0) | ... BI16: =ROUND(SUM($AX15:BI15),0)-ROUND(SUM($AX15:BH15),0)
A17: Лиды | B17: =IF('01_Вводные'!$B$25>0,ROUNDUP(ROUND(B15/'01_Вводные'!$B$25,10),0),0) | C17: =IF('01_Вводные'!$B$25>0,ROUNDUP(ROUND(C15/'01_Вводные'!$B$25,10),0),0) | D17: =IF('01_Вводные'!$B$25>0,ROUNDUP(ROUND(D15/'01_Вводные'!$B$25,10),0),0) | E17: =IF('01_Вводные'!$B$25>0,ROUNDUP(ROUND(E15/'01_Вводные'!$B$25,10),0),0) | F17: =IF('01_Вводные'!$B$25>0,ROUNDUP(ROUND(F15/'01_Вводные'!$B$25,10),0),0) | G17: =IF('01_Вводные'!$B$25>0,ROUNDUP(ROUND(G15/'01_Вводные'!$B$25,10),0),0) | H17: =IF('01_Вводные'!$B$25>0,ROUNDUP(ROUND(H15/'01_Вводные'!$B$25,10),0),0) | I17: =IF('01_Вводные'!$B$25>0,ROUNDUP(ROUND(I15/'01_Вводные'!$B$25,10),0),0) | ... BI17: =IF('01_Вводные'!$B$25>0,ROUNDUP(ROUND(BI15/'01_Вводные'!$B$25,10),0),0)
