Workbook
Name MeanMinAge16: '07_Тарифы'!$X$39
Name MeanMinAge09: '07_Тарифы'!$X$32
Name RevenueAge09: '07_Тарифы'!$B$32:$U$32
Name ThresholdAge23: '07_Тарифы'!$B$136:$U$136
Name CapacityYear2: '07_Тарифы'!$W$36:$W$47
Name WeightedRevAge10: '07_Тарифы'!$B$153:$U$153
Name MinimumAge12: '07_Тарифы'!$B$65:$U$65
Name УчитыватьИсторию: '01_Вводные'!$B$322
Name ДатаИндексацииЗП: '01_Вводные'!$B$251
Name СтавкаУСН: '01_Вводные'!$B$156
Name RevenueAge25: '07_Тарифы'!$B$48:$U$48
Name WeightedRevAge25: '07_Тарифы'!$B$168:$U$168
Name WeightedMinAge22: '07_Тарифы'!$B$195:$U$195
Name WeightedMinAge16: '07_Тарифы'!$B$189:$U$189
Name CapacityAge09: '07_Тарифы'!$W$32
Name CAPEXРазовый: '01_Вводные'!$B$287
Name MinimumAge03: '07_Тарифы'!$B$56:$U$56
Name ДетиК12Мес: '01_Вводные'!$B$46
Name WeightedMinAge14: '07_Тарифы'!$B$187:$U$187
Name ДатаLegacy: '01_Вводные'!$B$244
Name MinimumAge09: '07_Тарифы'!$B$62:$U$62
Name WeightedRevAge15: '07_Тарифы'!$B$158:$U$158
Name СреднийФиксТочки: '01_Вводные'!$B$52
Name RevenueAge14: '07_Тарифы'!$B$37:$U$37
Name WeightedMinAge10: '07_Тарифы'!$B$183:$U$183
Name CAPEXДата: '01_Вводные'!$B$289
Name WeightedRevAge17: '07_Тарифы'!$B$160:$U$160
Name MinimumAge16: '07_Тарифы'!$B$69:$U$69
Name CAPEXБаза: '01_Вводные'!$B$288
Name RevenueAge03: '07_Тарифы'!$B$26:$U$26
Name ERPШколВБазе: '01_Вводные'!$B$106
Name ЛагСледующихШкол: '01_Вводные'!$B$311
Name CapacityAge11: '07_Тарифы'!$W$34
Name CapacityAge07: '07_Тарифы'!$W$30
Name ДатаОфисМенеджера: '01_Вводные'!$B$247
Name ПремияГДвБазе: '01_Вводные'!$D$138
Name RevenueAge02: '07_Тарифы'!$B$25:$U$25
Name ThresholdAge13: '07_Тарифы'!$B$126:$U$126
Name ПрочиеIT: '01_Вводные'!$B$110
Name ЗапасДляЗайма: '01_Вводные'!$B$310
Name WeightedRevAge22: '07_Тарифы'!$B$165:$U$165
Name СуммаForbes: '01_Вводные'!$B$32
Name RevenueAge06: '07_Тарифы'!$B$29:$U$29
Name WeightedMinAge07: '07_Тарифы'!$B$180:$U$180
Name MinimumAge13: '07_Тарифы'!$B$66:$U$66
Name MeanMinAge17: '07_Тарифы'!$X$40
Name NetGross: '01_Вводные'!$B$132
Name ШколыСтарт: '01_Вводные'!$B$9
Name ДатаЗаменыДиректора: '01_Вводные'!$B$255
Name CapacityAge14: '07_Тарифы'!$W$37
Name ШколНаПродажу: '01_Вводные'!$B$22
Name MinimumAge15: '07_Тарифы'!$B$68:$U$68
Name РостДетей: '01_Вводные'!$B$12
Name CapacityAge22: '07_Тарифы'!$W$45
Name RevenueAge15: '07_Тарифы'!$B$38:$U$38
Name ОфисМенеджерNet: '01_Вводные'!$B$133
Name ДатаОсобогоЛага: '01_Вводные'!$B$242
Name ЗакрытиеГод: '01_Вводные'!$B$13
Name RevenueAge19: '07_Тарифы'!$B$42:$U$42
Name ДоляФКПаушальные: '01_Вводные'!$B$59

Sheet 00_Дашборд
B2: Финмодель «Спартак» — итог | G2: Сценарий: | H2: =СценарийТекст | I2: #gid=322657005&range=B192
B3: ="старт "&TEXT(MONTH(СтартМодели),"00")&"."&YEAR(СтартМодели)&" · горизонт "&ГоризонтМес&" мес." | G3: Сезон 25/26 в итоге: | H3: =УчитыватьИсторию | I3: #gid=322657005&range=B322
G4: =IF(УчитыватьИсторию="Да","Колонка слева — факт сезона 25/26, итог справа считает и его.","Колонка слева пуста: итог только за пять лет прогноза.")&" Сценарий пересчитывает всю модель, история — только показ."
B5: Показатель | C5: Сезон 25/26 09.2025 – 07.2026 | D5: ="Год 1"&CHAR(10)&TEXT(MONTH(DATE(YEAR(СтартМодели),MONTH(СтартМодели)+0,1)),"00")&"."&YEAR(DATE(YEAR(СтартМодели),MONTH(СтартМодели)+0,1))&" – "&TEXT(MONTH(DATE(YEAR(СтартМодели),MONTH(СтартМодели)+11,1)),"00")&"."&YEAR(DATE(YEAR(СтартМодели),MONTH(СтартМодели)+11,1)) | E5: ="Год 2"&CHAR(10)&TEXT(MONTH(DATE(YEAR(СтартМодели),MONTH(СтартМодели)+12,1)),"00")&"."&YEAR(DATE(YEAR(СтартМодели),MONTH(СтартМодели)+12,1))&" – "&TEXT(MONTH(DATE(YEAR(СтартМодели),MONTH(СтартМодели)+23,1)),"00")&"."&YEAR(DATE(YEAR(СтартМодели),MONTH(СтартМодели)+23,1)) | F5: ="Год 3"&CHAR(10)&TEXT(MONTH(DATE(YEAR(СтартМодели),MONTH(СтартМодели)+24,1)),"00")&"."&YEAR(DATE(YEAR(СтартМодели),MONTH(СтартМодели)+24,1))&" – "&TEXT(MONTH(DATE(YEAR(СтартМодели),MONTH(СтартМодели)+35,1)),"00")&"."&YEAR(DATE(YEAR(СтартМодели),MONTH(СтартМодели)+35,1)) | G5: ="Год 4"&CHAR(10)&TEXT(MONTH(DATE(YEAR(СтартМодели),MONTH(СтартМодели)+36,1)),"00")&"."&YEAR(DATE(YEAR(СтартМодели),MONTH(СтартМодели)+36,1))&" – "&TEXT(MONTH(DATE(YEAR(СтартМодели),MONTH(СтартМодели)+47,1)),"00")&"."&YEAR(DATE(YEAR(СтартМодели),MONTH(СтартМодели)+47,1)) | H5: ="Год 5"&CHAR(10)&TEXT(MONTH(DATE(YEAR(СтартМодели),MONTH(СтартМодели)+48,1)),"00")&"."&YEAR(DATE(YEAR(СтартМодели),MONTH(СтартМодели)+48,1))&" – "&TEXT(MONTH(DATE(YEAR(СтартМодели),MONTH(СтартМодели)+59,1)),"00")&"."&YEAR(DATE(YEAR(СтартМодели),MONTH(СтартМодели)+59,1)) | I5: ="Итого 5 лет"&CHAR(10)&TEXT(MONTH(DATE(YEAR(СтартМодели),MONTH(СтартМодели)+0,1)),"00")&"."&YEAR(DATE(YEAR(СтартМодели),MONTH(СтартМодели)+0,1))&" – "&TEXT(MONTH(DATE(YEAR(СтартМодели),MONTH(СтартМодели)+59,1)),"00")&"."&YEAR(DATE(YEAR(СтартМодели),MONTH(СтартМодели)+59,1)) | J5: С сезоном 25/26
B6: Паушальные взносы | C6: =IF(УчитыватьИсторию="Да",'01_Вводные'!$B$324,"") | D6: =SUM('02_Результат'!L12:'02_Результат'!W12) | E6: =SUM('02_Результат'!X12:'02_Результат'!AI12) | F6: =SUM('02_Результат'!AJ12:'02_Результат'!AU12) | G6: =SUM('02_Результат'!AV12:'02_Результат'!BG12) | H6: =SUM('02_Результат'!BH12:'02_Результат'!BS12) | I6: =SUM('02_Результат'!L12:'02_Результат'!BS12) | J6: =I6+IF(УчитыватьИсторию="Да",'01_Вводные'!$B$324,0)
B7: Роялти | C7: =IF(УчитыватьИсторию="Да",'01_Вводные'!$B$325,"") | D7: =SUM('02_Результат'!L13:'02_Результат'!W13) | E7: =SUM('02_Результат'!X13:'02_Результат'!AI13) | F7: =SUM('02_Результат'!AJ13:'02_Результат'!AU13) | G7: =SUM('02_Результат'!AV13:'02_Результат'!BG13) | H7: =SUM('02_Результат'!BH13:'02_Результат'!BS13) | I7: =SUM('02_Результат'!L13:'02_Результат'!BS13) | J7: =I7+IF(УчитыватьИсторию="Да",'01_Вводные'!$B$325,0)
B8: Мерч | C8: =IF(УчитыватьИсторию="Да",'01_Вводные'!$B$326,"") | D8: =SUM('02_Результат'!L14:'02_Результат'!W14) | E8: =SUM('02_Результат'!X14:'02_Результат'!AI14) | F8: =SUM('02_Результат'!AJ14:'02_Результат'!AU14) | G8: =SUM('02_Результат'!AV14:'02_Результат'!BG14) | H8: =SUM('02_Результат'!BH14:'02_Результат'!BS14) | I8: =SUM('02_Результат'!L14:'02_Результат'!BS14) | J8: =I8+IF(УчитыватьИсторию="Да",'01_Вводные'!$B$326,0)
B9: Выручка без НДС | C9: =IF(УчитыватьИсторию="Да",'01_Вводные'!$B$327,"") | D9: =SUM('02_Результат'!L16:'02_Результат'!W16) | E9: =SUM('02_Результат'!X16:'02_Результат'!AI16) | F9: =SUM('02_Результат'!AJ16:'02_Результат'!AU16) | G9: =SUM('02_Результат'!AV16:'02_Результат'!BG16) | H9: =SUM('02_Результат'!BH16:'02_Результат'!BS16) | I9: =SUM('02_Результат'!L16:'02_Результат'!BS16) | J9: =I9+IF(УчитыватьИсторию="Да",'01_Вводные'!$B$327,0)
B11: Прямые расходы | C11: =IF(УчитыватьИсторию="Да",'01_Вводные'!$B$328,"") | D11: =SUM('02_Результат'!L22:'02_Результат'!W22) | E11: =SUM('02_Результат'!X22:'02_Результат'!AI22) | F11: =SUM('02_Результат'!AJ22:'02_Результат'!AU22) | G11: =SUM('02_Результат'!AV22:'02_Результат'!BG22) | H11: =SUM('02_Результат'!BH22:'02_Результат'!BS22) | I11: =SUM('02_Результат'!L22:'02_Результат'!BS22) | J11: =I11+IF(УчитыватьИсторию="Да",'01_Вводные'!$B$328,0)
B12: Валовая прибыль | C12: =IF(УчитыватьИсторию="Да",'01_Вводные'!$B$329,"") | D12: =SUM('02_Результат'!L23:'02_Результат'!W23) | E12: =SUM('02_Результат'!X23:'02_Результат'!AI23) | F12: =SUM('02_Результат'!AJ23:'02_Результат'!AU23) | G12: =SUM('02_Результат'!AV23:'02_Результат'!BG23) | H12: =SUM('02_Результат'!BH23:'02_Результат'!BS23) | I12: =SUM('02_Результат'!L23:'02_Результат'!BS23) | J12: =I12+IF(УчитыватьИсторию="Да",'01_Вводные'!$B$329,0)
B13: ФОТ и кадровые расходы | C13: =IF(УчитыватьИсторию="Да",'01_Вводные'!$B$330,"") | D13: =SUM('02_Результат'!L24:'02_Результат'!W24) | E13: =SUM('02_Результат'!X24:'02_Результат'!AI24) | F13: =SUM('02_Результат'!AJ24:'02_Результат'!AU24) | G13: =SUM('02_Результат'!AV24:'02_Результат'!BG24) | H13: =SUM('02_Результат'!BH24:'02_Результат'!BS24) | I13: =SUM('02_Результат'!L24:'02_Результат'!BS24) | J13: =I13+IF(УчитыватьИсторию="Да",'01_Вводные'!$B$330,0)
B14: OPEX — прочие (без ФОТ) | C14: =IF(УчитыватьИсторию="Да",'01_Вводные'!$B$331,"") | D14: =SUM('02_Результат'!L31:'02_Результат'!W31) | E14: =SUM('02_Результат'!X31:'02_Результат'!AI31) | F14: =SUM('02_Результат'!AJ31:'02_Результат'!AU31) | G14: =SUM('02_Результат'!AV31:'02_Результат'!BG31) | H14: =SUM('02_Результат'!BH31:'02_Результат'!BS31) | I14: =SUM('02_Результат'!L31:'02_Результат'!BS31) | J14: =I14+IF(УчитыватьИсторию="Да",'01_Вводные'!$B$331,0)
B15: EBITDA | C15: =IF(УчитыватьИсторию="Да",'01_Вводные'!$B$332,"") | D15: =SUM('02_Результат'!L33:'02_Результат'!W33) | E15: =SUM('02_Результат'!X33:'02_Результат'!AI33) | F15: =SUM('02_Результат'!AJ33:'02_Результат'!AU33) | G15: =SUM('02_Результат'!AV33:'02_Результат'!BG33) | H15: =SUM('02_Результат'!BH33:'02_Результат'!BS33) | I15: =SUM('02_Результат'!L33:'02_Результат'!BS33) | J15: =I15+IF(УчитыватьИсторию="Да",'01_Вводные'!$B$332,0)
B16: УСН / минимальный налог | C16: =IF(УчитыватьИсторию="Да",'01_Вводные'!$B$333,"") | D16: =SUM('02_Результат'!L35:'02_Результат'!W35) | E16: =SUM('02_Результат'!X35:'02_Результат'!AI35) | F16: =SUM('02_Результат'!AJ35:'02_Результат'!AU35) | G16: =SUM('02_Результат'!AV35:'02_Результат'!BG35) | H16: =SUM('02_Результат'!BH35:'02_Результат'!BS35) | I16: =SUM('02_Результат'!L35:'02_Результат'!BS35) | J16: =I16+IF(УчитыватьИсторию="Да",'01_Вводные'!$B$333,0)
B17: Прибыль после налога | C17: =IF(УчитыватьИсторию="Да",'01_Вводные'!$B$334,"") | D17: =SUM('02_Результат'!L36:'02_Результат'!W36) | E17: =SUM('02_Результат'!X36:'02_Результат'!AI36) | F17: =SUM('02_Результат'!AJ36:'02_Результат'!AU36) | G17: =SUM('02_Результат'!AV36:'02_Результат'!BG36) | H17: =SUM('02_Результат'!BH36:'02_Результат'!BS36) | I17: =SUM('02_Результат'!L36:'02_Результат'!BS36) | J17: =I17+IF(УчитыватьИсторию="Да",'01_Вводные'!$B$334,0)
B19: Денежный поток за период | C19: =IF(УчитыватьИсторию="Да",'01_Вводные'!$B$335,"") | D19: =SUM('02_Результат'!L58:'02_Результат'!W58) | E19: =SUM('02_Результат'!X58:'02_Результат'!AI58) | F19: =SUM('02_Результат'!AJ58:'02_Результат'!AU58) | G19: =SUM('02_Результат'!AV58:'02_Результат'!BG58) | H19: =SUM('02_Результат'!BH58:'02_Результат'!BS58) | I19: =SUM('02_Результат'!L58:'02_Результат'!BS58) | J19: =I19+IF(УчитыватьИсторию="Да",'01_Вводные'!$B$335,0)
B20: Деньги на конец периода | C20: =IF(УчитыватьИсторию="Да",'01_Вводные'!$B$336,"") | D20: ='02_Результат'!W59 | E20: ='02_Результат'!AI59 | F20: ='02_Результат'!AU59 | G20: ='02_Результат'!BG59 | H20: ='02_Результат'!BS59 | I20: ='02_Результат'!BS59 | J20: =I20
B22: Школы на конец периода | C22: =IF(УчитыватьИсторию="Да",'01_Вводные'!$B$337,"") | D22: ='02_Результат'!W7 | E22: ='02_Результат'!AI7 | F22: ='02_Результат'!AU7 | G22: ='02_Результат'!BG7 | H22: ='02_Результат'!BS7 | I22: ='02_Результат'!BS7 | J22: =I22
B23: Партнёры на конец периода | C23: =IF(УчитыватьИсторию="Да",'01_Вводные'!$B$338,"") | D23: ='02_Результат'!W8 | E23: ='02_Результат'!AI8 | F23: ='02_Результат'!AU8 | G23: ='02_Результат'!BG8 | H23: ='02_Результат'!BS8 | I23: ='02_Результат'!BS8 | J23: =I23
B24: Дети, среднее за период | C24: =IF(УчитыватьИсторию="Да",'01_Вводные'!$B$339,"") | D24: =AVERAGE('02_Результат'!L9:'02_Результат'!W9) | E24: =AVERAGE('02_Результат'!X9:'02_Результат'!AI9) | F24: =AVERAGE('02_Результат'!AJ9:'02_Результат'!AU9) | G24: =AVERAGE('02_Результат'!AV9:'02_Результат'!BG9) | H24: =AVERAGE('02_Результат'!BH9:'02_Результат'!BS9) | I24: =AVERAGE('02_Результат'!L9:'02_Результат'!BS9) | J24: =I24 | K24: дети на март сезона
B25: Дети на пике сезона (март) | D25: =SUMPRODUCT((MONTH('02_Результат'!L$5:W$5)=3)*'02_Результат'!L9:W9) | E25: =SUMPRODUCT((MONTH('02_Результат'!X$5:AI$5)=3)*'02_Результат'!X9:AI9) | F25: =SUMPRODUCT((MONTH('02_Результат'!AJ$5:AU$5)=3)*'02_Результат'!AJ9:AU9) | G25: =SUMPRODUCT((MONTH('02_Результат'!AV$5:BG$5)=3)*'02_Результат'!AV9:BG9) | H25: =SUMPRODUCT((MONTH('02_Результат'!BH$5:BS$5)=3)*'02_Результат'!BH9:BS9) | I25: =H25 | J25: =I25
B26: На что смотреть
B27: Минимальный остаток денег за все 60 месяцев | C27: =MIN('02_Результат'!L59:'02_Результат'!BS59)
B28: Месяцев с отрицательным остатком | C28: =COUNTIF('02_Результат'!L59:'02_Результат'!BS59,"<0")
B29: Срок закрытия займа клубу, мес. | C29: =IF('06_Деньги'!BS19>0.01,"не закрыт за 60 мес.",SUMPRODUCT(--('06_Деньги'!L19:BS19>0.01))+1) | D29: {=IF(ISNUMBER(C29),INDEX('02_Результат'!$L$5:$BS$5,C29),"")}
B30: Рентабельность EBITDA за 5 лет | C30: =IF(I9=0,0,I15/I9)
B32: Ограничение: минимальный остаток на счёте | C32: =МинОстатокДляЗайма
B33: Клубу возвращаем займ только теми деньгами, что остаются сверх этого порога и сверх запаса на ближайшие убыточные месяцы. Сезон проседает летом — в июле и августе активны 14 % детей от мартовского уровня, а аренда и ФОТ идут как обычно, — и без такого резерва платёж клубу уводил счёт в минус. Поэтому в первые два года «Чистый поток за год» близок к нулю: вся свободная сумма уходит на склад формы и в погашение займа, а остаток на конец упирается в порог. Это не потеря денег, а их перекладывание в склад и в уменьшение долга — видно по строкам «Закупка на склад» и «Займ на конец» листа 06_Деньги. Порог меняется на листе 01_Вводные.
B35: Как это выглядит
B36: Шесть графиков по годам — значения подписаны на самих точках, деньги в миллионах. Нижний по месяцам: склад живёт внутри года, годовой срез его не показывает. Над каждым графиком строка «что смотреть».
B38: Выручка и EBITDA по годам. Масштаб бизнеса и сколько от него остаётся. Разрыв между столбцами — операционные расходы года. | L38: Откуда выручка: паушальные, роялти, мерч. Чем дальше год, тем меньше доля разовых паушальных и больше повторяющихся роялти и мерча — это и есть устойчивость модели.
B59: Продажи франшиз и открытия школ за год. Открытий больше, чем продаж: один партнёр со временем открывает несколько школ. Разрыв — это лаг открытия следующих школ. | L59: Сеть на конец года: школы и дети. Накопленный размер сети. Дети на правой оси: школа выходит на мощность за два года, поэтому линия отстаёт от столбцов.
B80: Форма: выручка и прибыль за год. Мерч — второй по размеру источник денег. Нижний столбец — что остаётся до того, как клуб заберёт свою долю. | L80: Займ клубу: погашено за год и остаток на конец. Как гасится займ на мерч. Гасим только свободными деньгами — линия остатка идёт вниз ступенями, а не равномерно.
B101: Склад формы по месяцам. Хватает ли формы на складе. Пока синяя линия выше оранжевой, спрос обеспечен; провал под неё — дефицит формы.
B123: Где что лежит
B124: 01_Вводные | C124: Единственное место, где что-то вводится руками
B125: 02_Результат | C125: БДР и БДДС: годы слева, месяцы справа
B126: 03_Сеть | C126: Расшифровка: продажи, открытия, школы, дети
B127: 04_Доходы | C127: Расшифровка: паушальные, роялти, мерч
B128: 05_Расходы | C128: Расшифровка: ФОТ, OPEX, выплаты ФК
...

Sheet 01_Вводные
A1: Финмодель Спартак — единый лист вводных
A2: Легенда: | B2: ввод | C2: уточнить | D2: переключатель | E2: добавлено по договору | F2: формула — не трогать | G2: #gid=561835286 | H2: #gid=724336794
A3: Правило работы | B3: Менять жёлтые ячейки только здесь. Сценарий: B192. Чувствительность: B233:B234. Параметры, микс и история собраны на одном листе.
A4: #gid=322657005&range=A190 | G4: #gid=322657005&range=A190 | H4: #gid=322657005&range=A260
A5: 1. Календарь, стартовая сеть и оборотный капитал
A6: Параметр | B6: Значение | C6: Ед. | D6: Статус / источник | E6: Комментарий | G6: #gid=322657005&range=A232 | H6: #gid=322657005&range=A285
A7: Дата старта модели | B7: 46266 | C7: дата | E7: Сезон считается от даты старта: 12 месяцев — один сезон. Сезонность посещаемости, веса плана продаж и согласованный мерч привязаны к календарю и не зависят от месяца старта.
A8: Горизонт прогноза | B8: 60 | C8: мес. | G8: #gid=322657005&range=A309 | H8: #gid=322657005&range=A321
A9: Активные школы действующей сети на старте | B9: 104 | C9: шт. | D9: Фактический реестр на 09.09.2026 | E9: 104 действующие школы у 51 действующего партнёра; 3 новых партнёра пока без школ и в 104 не входят.
A10: Активные юрлица на старте | B10: 49 | C10: шт. | D10: Реестр сети 21.08.2026
A11: Дети действующей сети, 100% база | B11: 5200 | C11: чел.
A12: Рост детей действующей сети | B12: 0.1 | C12: %/год | E12: Сложный рост, пересчёт каждый сентябрь
A13: Закрытие школ / юрлиц | B13: 0.03 | C13: %/год | E13: =IF($B$13=0,"Механика работает, пока 0%","Закрывается "&ROUND($B$13*100,1)&" % школ и юрлиц в год; помесячно через коэффициент B14")
A14: Месячный коэффициент сохранения | B14: =(1-B13)^(1/12) | C14: коэфф. | E14: Технический коэффициент для закрытий
A15: Лаг продажа → открытие | B15: 2 | C15: мес. | E15: Продажа, открытие и ERP — разные события
A16: Новых юрлиц на 1 продажу | B16: 1 | C16: юрлиц/продажу | D16: Временно | E16: Связь продаж с новыми юрлицами. Пока 1:1; отдельно от количества школ на партнёра.
A17: Стартовый денежный остаток | B17: 187878 | C17: ₽ | D17: ДДС на 02.07.2026
A18: Дебиторка | B18: =$B$225*$F$203 | C18: дней | D18: Расчет по сценарию | E18: Базовое допущение | G18: ← формула; база: B225
A19: Кредиторка | B19: 15 | C19: дней | E19: Базовое допущение
A20: Доля поступления в текущем месяце | B20: =MAX(0,MIN(1,(30-B18)/30)) | C20: % | E20: 15 дней ≈ 50% текущий / 50% следующий месяц
A21: Доля оплаты в текущем месяце | B21: =MAX(0,MIN(1,(30-B19)/30)) | C21: % | E21: 15 дней ≈ 50% текущий / 50% следующий месяц
A22: Новых школ на 1 продажу / нового партнёра | B22: 1.1 | C22: школ/продажу | E22: ="Новый партнёр открывает "&ROUND($B$22,1)&" школы. Действующая сеть: 2,04 школы на партнёра (104 на 51)"
A23: 2. Продажи франшиз и маркетинг
A24: Параметр | B24: Значение | C24: Ед. | D24: Статус / источник | E24: Комментарий
A25: Конверсия лид → продажа | B25: 0.03 | C25: %
A26: Таргет на будущую продажу | B26: =$B$224*$F$202 | C26: ₽/продажа | D26: Расчет по сценарию | E26: Обычно M-2; для октября 2026 исключение M-1 | G26: ← формула; база: B224
A27: Лаг таргета до продажи | B27: 2 | C27: мес. | E27: Октябрь 2026 — отдельное исключение
A28: БИБОСС — сумма | B28: 200000 | C28: ₽ | E28: Ежегодно
A29: БИБОСС — месяц | B29: 10 | C29: номер месяца | E29: Октябрь
A30: TopFranchise — сумма | B30: 200000 | C30: ₽ | E30: Ежегодно
A31: TopFranchise — месяц | B31: 11 | C31: номер месяца | E31: Ноябрь
A32: Forbes — сумма | B32: 200000 | C32: ₽ | E32: Ежегодно
A33: Forbes — месяц | B33: 12 | C33: номер месяца | E33: Декабрь
A34: 2а. Планы продаж и сезонность (веса — по календарным месяцам, первый месяц модели без продаж)
A35: Сезон | B35: Годовой план | C35: Сен | D35: Окт | E35: Ноя | F35: Дек | G35: Янв | H35: Фев | I35: Мар | J35: Апр | K35: Май | L35: Июн | M35: Июл | N35: Авг | O35: Контроль
A36: 1 | B36: =$B$210*$F$198 | C36: 0.18 | D36: 0.04 | E36: 0.03 | F36: 0.02 | G36: 0.08 | H36: 0.13 | I36: 0.1 | J36: 0.06 | K36: 0.08 | L36: 0.05 | M36: 0.09 | N36: 0.14 | O36: =SUM(C36:N36)
A37: 2 | B37: =$B$211*$F$198 | C37: 0.18 | D37: 0.09 | E37: 0.03 | F37: 0.02 | G37: 0.08 | H37: 0.13 | I37: 0.05 | J37: 0.06 | K37: 0.08 | L37: 0.05 | M37: 0.09 | N37: 0.14 | O37: =SUM(C37:N37)
A38: 3 | B38: =$B$212*$F$198 | C38: 0.18 | D38: 0.09 | E38: 0.03 | F38: 0.02 | G38: 0.08 | H38: 0.13 | I38: 0.05 | J38: 0.06 | K38: 0.08 | L38: 0.05 | M38: 0.09 | N38: 0.14 | O38: =SUM(C38:N38)
A39: 4 | B39: =$B$213*$F$198 | C39: 0.18 | D39: 0.09 | E39: 0.03 | F39: 0.02 | G39: 0.08 | H39: 0.13 | I39: 0.05 | J39: 0.06 | K39: 0.08 | L39: 0.05 | M39: 0.09 | N39: 0.14 | O39: =SUM(C39:N39)
A40: 5 | B40: =$B$214*$F$198 | C40: 0.18 | D40: 0.09 | E40: 0.03 | F40: 0.02 | G40: 0.08 | H40: 0.13 | I40: 0.05 | J40: 0.06 | K40: 0.08 | L40: 0.05 | M40: 0.09 | N40: 0.14 | O40: =SUM(C40:N40)
...

Sheet 02_Результат
B1: Результат: БДР и БДДС
B2: Начисления и деньги на одном листе, но в разных блоках. Слева итоги по годам, справа те же строки по месяцам.
B4: Показатель | C4: Ед. | D4: Как считается | E4: Год 1 | F4: Год 2 | G4: Год 3 | H4: Год 4 | I4: Год 5 | J4: Итого 5 лет | L4: М1 | M4: М2 | N4: М3 | O4: М4 | P4: М5 | Q4: М6 | R4: М7 | S4: М8 | T4: М9 | U4: М10 | V4: М11 | W4: М12 | X4: М13 | Y4: М14 | Z4: М15 | AA4: М16 | AB4: М17 | AC4: М18 | AD4: М19 | AE4: М20 | AF4: М21 | AG4: М22 | AH4: М23 | AI4: М24 | AJ4: М25 | AK4: М26 | AL4: М27 | AM4: М28 | AN4: М29 | AO4: М30 | AP4: М31 | AQ4: М32 | AR4: М33 | AS4: М34 | AT4: М35 | AU4: М36 | AV4: М37 | AW4: М38 | AX4: М39 | AY4: М40 | AZ4: М41 | BA4: М42 | BB4: М43 | BC4: М44 | BD4: М45 | BE4: М46 | BF4: М47 | BG4: М48 | BH4: М49 | BI4: М50 | BJ4: М51 | BK4: М52 | BL4: М53 | BM4: М54 | BN4: М55 | BO4: М56 | BP4: М57 | BQ4: М58 | BR4: М59 | BS4: М60 | BT4: тех. 1 | BU4: тех. 2 | BV4: тех. 3 | BW4: тех. 4 | BX4: тех. 5 | BY4: тех. 6
E5: =TEXT(MONTH(DATE(YEAR(СтартМодели),MONTH(СтартМодели)+0,1)),"00")&"."&YEAR(DATE(YEAR(СтартМодели),MONTH(СтартМодели)+0,1))&" – "&TEXT(MONTH(DATE(YEAR(СтартМодели),MONTH(СтартМодели)+11,1)),"00")&"."&YEAR(DATE(YEAR(СтартМодели),MONTH(СтартМодели)+11,1)) | F5: =TEXT(MONTH(DATE(YEAR(СтартМодели),MONTH(СтартМодели)+12,1)),"00")&"."&YEAR(DATE(YEAR(СтартМодели),MONTH(СтартМодели)+12,1))&" – "&TEXT(MONTH(DATE(YEAR(СтартМодели),MONTH(СтартМодели)+23,1)),"00")&"."&YEAR(DATE(YEAR(СтартМодели),MONTH(СтартМодели)+23,1)) | G5: =TEXT(MONTH(DATE(YEAR(СтартМодели),MONTH(СтартМодели)+24,1)),"00")&"."&YEAR(DATE(YEAR(СтартМодели),MONTH(СтартМодели)+24,1))&" – "&TEXT(MONTH(DATE(YEAR(СтартМодели),MONTH(СтартМодели)+35,1)),"00")&"."&YEAR(DATE(YEAR(СтартМодели),MONTH(СтартМодели)+35,1)) | H5: =TEXT(MONTH(DATE(YEAR(СтартМодели),MONTH(СтартМодели)+36,1)),"00")&"."&YEAR(DATE(YEAR(СтартМодели),MONTH(СтартМодели)+36,1))&" – "&TEXT(MONTH(DATE(YEAR(СтартМодели),MONTH(СтартМодели)+47,1)),"00")&"."&YEAR(DATE(YEAR(СтартМодели),MONTH(СтартМодели)+47,1)) | I5: =TEXT(MONTH(DATE(YEAR(СтартМодели),MONTH(СтартМодели)+48,1)),"00")&"."&YEAR(DATE(YEAR(СтартМодели),MONTH(СтартМодели)+48,1))&" – "&TEXT(MONTH(DATE(YEAR(СтартМодели),MONTH(СтартМодели)+59,1)),"00")&"."&YEAR(DATE(YEAR(СтартМодели),MONTH(СтартМодели)+59,1)) | J5: =TEXT(MONTH(DATE(YEAR(СтартМодели),MONTH(СтартМодели)+0,1)),"00")&"."&YEAR(DATE(YEAR(СтартМодели),MONTH(СтартМодели)+0,1))&" – "&TEXT(MONTH(DATE(YEAR(СтартМодели),MONTH(СтартМодели)+59,1)),"00")&"."&YEAR(DATE(YEAR(СтартМодели),MONTH(СтартМодели)+59,1)) | L5: =DATE(YEAR(СтартМодели),MONTH(СтартМодели)+1-1,1) | M5: =DATE(YEAR(СтартМодели),MONTH(СтартМодели)+2-1,1) | N5: =DATE(YEAR(СтартМодели),MONTH(СтартМодели)+3-1,1) | O5: =DATE(YEAR(СтартМодели),MONTH(СтартМодели)+4-1,1) | P5: =DATE(YEAR(СтартМодели),MONTH(СтартМодели)+5-1,1) | Q5: =DATE(YEAR(СтартМодели),MONTH(СтартМодели)+6-1,1) | R5: =DATE(YEAR(СтартМодели),MONTH(СтартМодели)+7-1,1) | S5: =DATE(YEAR(СтартМодели),MONTH(СтартМодели)+8-1,1) | T5: =DATE(YEAR(СтартМодели),MONTH(СтартМодели)+9-1,1) | U5: =DATE(YEAR(СтартМодели),MONTH(СтартМодели)+10-1,1) | V5: =DATE(YEAR(СтартМодели),MONTH(СтартМодели)+11-1,1) | W5: =DATE(YEAR(СтартМодели),MONTH(СтартМодели)+12-1,1) | X5: =DATE(YEAR(СтартМодели),MONTH(СтартМодели)+13-1,1) | Y5: =DATE(YEAR(СтартМодели),MONTH(СтартМодели)+14-1,1) | Z5: =DATE(YEAR(СтартМодели),MONTH(СтартМодели)+15-1,1) | AA5: =DATE(YEAR(СтартМодели),MONTH(СтартМодели)+16-1,1) | AB5: =DATE(YEAR(СтартМодели),MONTH(СтартМодели)+17-1,1) | AC5: =DATE(YEAR(СтартМодели),MONTH(СтартМодели)+18-1,1) | AD5: =DATE(YEAR(СтартМодели),MONTH(СтартМодели)+19-1,1) | AE5: =DATE(YEAR(СтартМодели),MONTH(СтартМодели)+20-1,1) | AF5: =DATE(YEAR(СтартМодели),MONTH(СтартМодели)+21-1,1) | AG5: =DATE(YEAR(СтартМодели),MONTH(СтартМодели)+22-1,1) | AH5: =DATE(YEAR(СтартМодели),MONTH(СтартМодели)+23-1,1) | AI5: =DATE(YEAR(СтартМодели),MONTH(СтартМодели)+24-1,1) | AJ5: =DATE(YEAR(СтартМодели),MONTH(СтартМодели)+25-1,1) | AK5: =DATE(YEAR(СтартМодели),MONTH(СтартМодели)+26-1,1) | AL5: =DATE(YEAR(СтартМодели),MONTH(СтартМодели)+27-1,1) | AM5: =DATE(YEAR(СтартМодели),MONTH(СтартМодели)+28-1,1) | AN5: =DATE(YEAR(СтартМодели),MONTH(СтартМодели)+29-1,1) | AO5: =DATE(YEAR(СтартМодели),MONTH(СтартМодели)+30-1,1) | AP5: =DATE(YEAR(СтартМодели),MONTH(СтартМодели)+31-1,1) | AQ5: =DATE(YEAR(СтартМодели),MONTH(СтартМодели)+32-1,1) | AR5: =DATE(YEAR(СтартМодели),MONTH(СтартМодели)+33-1,1) | AS5: =DATE(YEAR(СтартМодели),MONTH(СтартМодели)+34-1,1) | AT5: =DATE(YEAR(СтартМодели),MONTH(СтартМодели)+35-1,1) | AU5: =DATE(YEAR(СтартМодели),MONTH(СтартМодели)+36-1,1) | AV5: =DATE(YEAR(СтартМодели),MONTH(СтартМодели)+37-1,1) | AW5: =DATE(YEAR(СтартМодели),MONTH(СтартМодели)+38-1,1) | AX5: =DATE(YEAR(СтартМодели),MONTH(СтартМодели)+39-1,1) | AY5: =DATE(YEAR(СтартМодели),MONTH(СтартМодели)+40-1,1) | AZ5: =DATE(YEAR(СтартМодели),MONTH(СтартМодели)+41-1,1) | BA5: =DATE(YEAR(СтартМодели),MONTH(СтартМодели)+42-1,1) | BB5: =DATE(YEAR(СтартМодели),MONTH(СтартМодели)+43-1,1) | BC5: =DATE(YEAR(СтартМодели),MONTH(СтартМодели)+44-1,1) | BD5: =DATE(YEAR(СтартМодели),MONTH(СтартМодели)+45-1,1) | BE5: =DATE(YEAR(СтартМодели),MONTH(СтартМодели)+46-1,1) | BF5: =DATE(YEAR(СтартМодели),MONTH(СтартМодели)+47-1,1) | BG5: =DATE(YEAR(СтартМодели),MONTH(СтартМодели)+48-1,1) | BH5: =DATE(YEAR(СтартМодели),MONTH(СтартМодели)+49-1,1) | BI5: =DATE(YEAR(СтартМодели),MONTH(СтартМодели)+50-1,1) | BJ5: =DATE(YEAR(СтартМодели),MONTH(СтартМодели)+51-1,1) | BK5: =DATE(YEAR(СтартМодели),MONTH(СтартМодели)+52-1,1) | BL5: =DATE(YEAR(СтартМодели),MONTH(СтартМодели)+53-1,1) | BM5: =DATE(YEAR(СтартМодели),MONTH(СтартМодели)+54-1,1) | BN5: =DATE(YEAR(СтартМодели),MONTH(СтартМодели)+55-1,1) | BO5: =DATE(YEAR(СтартМодели),MONTH(СтартМодели)+56-1,1) | BP5: =DATE(YEAR(СтартМодели),MONTH(СтартМодели)+57-1,1) | BQ5: =DATE(YEAR(СтартМодели),MONTH(СтартМодели)+58-1,1) | BR5: =DATE(YEAR(СтартМодели),MONTH(СтартМодели)+59-1,1) | BS5: =DATE(YEAR(СтартМодели),MONTH(СтартМодели)+60-1,1) | BT5: =DATE(YEAR(СтартМодели),MONTH(СтартМодели)+61-1,1) | BU5: =DATE(YEAR(СтартМодели),MONTH(СтартМодели)+62-1,1) | BV5: =DATE(YEAR(СтартМодели),MONTH(СтартМодели)+63-1,1) | BW5: =DATE(YEAR(СтартМодели),MONTH(СтартМодели)+64-1,1) | BX5: =DATE(YEAR(СтартМодели),MONTH(СтартМодели)+65-1,1) | BY5: =DATE(YEAR(СтартМодели),MONTH(СтартМодели)+66-1,1)
B6: Сеть (справочно)
B7: Школы всего | C7: шт. | D7: Подробности — на листе «Сеть» В колонках лет — значение на конец года, в «Итого» — на конец пятого года. Это остаток, а не сумма. | E7: =W7 | F7: =AI7 | G7: =AU7 | H7: =BG7 | I7: =BS7 | J7: =BS7 | L7: ='03_Сеть'!L60 | M7: ='03_Сеть'!M60 | N7: ='03_Сеть'!N60 | O7: ='03_Сеть'!O60 | P7: ='03_Сеть'!P60 | Q7: ='03_Сеть'!Q60 | R7: ='03_Сеть'!R60 | S7: ='03_Сеть'!S60 | ... BY7: ='03_Сеть'!BY60
B8: Партнёры (юрлица) | C8: шт. | D8: В колонках лет — значение на конец года, в «Итого» — на конец пятого года. Это остаток, а не сумма. | E8: =W8 | F8: =AI8 | G8: =AU8 | H8: =BG8 | I8: =BS8 | J8: =BS8 | L8: ='03_Сеть'!L61 | M8: ='03_Сеть'!M61 | N8: ='03_Сеть'!N61 | O8: ='03_Сеть'!O61 | P8: ='03_Сеть'!P61 | Q8: ='03_Сеть'!Q61 | R8: ='03_Сеть'!R61 | S8: ='03_Сеть'!S61 | ... BY8: ='03_Сеть'!BY61
B9: Дети, активные | C9: чел. | D9: В колонках лет — значение на конец года, в «Итого» — на конец пятого года. Это остаток, а не сумма. | E9: =W9 | F9: =AI9 | G9: =AU9 | H9: =BG9 | I9: =BS9 | J9: =BS9 | L9: ='03_Сеть'!L62 | M9: ='03_Сеть'!M62 | N9: ='03_Сеть'!N62 | O9: ='03_Сеть'!O62 | P9: ='03_Сеть'!P62 | Q9: ='03_Сеть'!Q62 | R9: ='03_Сеть'!R62 | S9: ='03_Сеть'!S62 | ... BY9: ='03_Сеть'!BY62
B11: БДР — начисления
B12: Паушальные взносы | C12: ₽ | D12: Без НДС | E12: =SUM(L12:W12) | F12: =SUM(X12:AI12) | G12: =SUM(AJ12:AU12) | H12: =SUM(AV12:BG12) | I12: =SUM(BH12:BS12) | J12: =SUM(L12:BS12) | L12: ='04_Доходы'!L14 | M12: ='04_Доходы'!M14 | N12: ='04_Доходы'!N14 | O12: ='04_Доходы'!O14 | P12: ='04_Доходы'!P14 | Q12: ='04_Доходы'!Q14 | R12: ='04_Доходы'!R14 | S12: ='04_Доходы'!S14 | ... BY12: ='04_Доходы'!BY14
B13: Роялти | C13: ₽ | D13: Без НДС | E13: =SUM(L13:W13) | F13: =SUM(X13:AI13) | G13: =SUM(AJ13:AU13) | H13: =SUM(AV13:BG13) | I13: =SUM(BH13:BS13) | J13: =SUM(L13:BS13) | L13: ='04_Доходы'!L103/(1+НДС) | M13: ='04_Доходы'!M103/(1+НДС) | N13: ='04_Доходы'!N103/(1+НДС) | O13: ='04_Доходы'!O103/(1+НДС) | P13: ='04_Доходы'!P103/(1+НДС) | Q13: ='04_Доходы'!Q103/(1+НДС) | R13: ='04_Доходы'!R103/(1+НДС) | S13: ='04_Доходы'!S103/(1+НДС) | ... BY13: ='04_Доходы'!BY103/(1+НДС)
B14: Мерч | C14: ₽ | D14: Без НДС | E14: =SUM(L14:W14) | F14: =SUM(X14:AI14) | G14: =SUM(AJ14:AU14) | H14: =SUM(AV14:BG14) | I14: =SUM(BH14:BS14) | J14: =SUM(L14:BS14) | L14: ='04_Доходы'!L132 | M14: ='04_Доходы'!M132 | N14: ='04_Доходы'!N132 | O14: ='04_Доходы'!O132 | P14: ='04_Доходы'!P132 | Q14: ='04_Доходы'!Q132 | R14: ='04_Доходы'!R132 | S14: ='04_Доходы'!S132 | ... BY14: ='04_Доходы'!BY132
B15: Лагеря | C15: ₽ | D15: Блок отключён переключателем на листе вводных | E15: =SUM(L15:W15) | F15: =SUM(X15:AI15) | G15: =SUM(AJ15:AU15) | H15: =SUM(AV15:BG15) | I15: =SUM(BH15:BS15) | J15: =SUM(L15:BS15) | L15: =0 | M15: =0 | N15: =0 | O15: =0 | P15: =0 | Q15: =0 | R15: =0 | S15: =0 | ... BY15: =0
B16: Выручка — всего | C16: ₽ | E16: =SUM(L16:W16) | F16: =SUM(X16:AI16) | G16: =SUM(AJ16:AU16) | H16: =SUM(AV16:BG16) | I16: =SUM(BH16:BS16) | J16: =SUM(L16:BS16) | L16: =SUM(L12:L15) | M16: =SUM(M12:M15) | N16: =SUM(N12:N15) | O16: =SUM(O12:O15) | P16: =SUM(P12:P15) | Q16: =SUM(Q12:Q15) | R16: =SUM(R12:R15) | S16: =SUM(S12:S15) | ... BY16: =SUM(BY12:BY15)
B17: COGS мерча | C17: ₽ | E17: =SUM(L17:W17) | F17: =SUM(X17:AI17) | G17: =SUM(AJ17:AU17) | H17: =SUM(AV17:BG17) | I17: =SUM(BH17:BS17) | J17: =SUM(L17:BS17) | L17: ='04_Доходы'!L133 | M17: ='04_Доходы'!M133 | N17: ='04_Доходы'!N133 | O17: ='04_Доходы'!O133 | P17: ='04_Доходы'!P133 | Q17: ='04_Доходы'!Q133 | R17: ='04_Доходы'!R133 | S17: ='04_Доходы'!S133 | ... BY17: ='04_Доходы'!BY133
B18: Логистика, возвраты, брак | C18: ₽ | E18: =SUM(L18:W18) | F18: =SUM(X18:AI18) | G18: =SUM(AJ18:AU18) | H18: =SUM(AV18:BG18) | I18: =SUM(BH18:BS18) | J18: =SUM(L18:BS18) | L18: ='04_Доходы'!L134 | M18: ='04_Доходы'!M134 | N18: ='04_Доходы'!N134 | O18: ='04_Доходы'!O134 | P18: ='04_Доходы'!P134 | Q18: ='04_Доходы'!Q134 | R18: ='04_Доходы'!R134 | S18: ='04_Доходы'!S134 | ... BY18: ='04_Доходы'!BY134
B19: Клубу: доля прибыли мерча | C19: ₽ | E19: =SUM(L19:W19) | F19: =SUM(X19:AI19) | G19: =SUM(AJ19:AU19) | H19: =SUM(AV19:BG19) | I19: =SUM(BH19:BS19) | J19: =SUM(L19:BS19) | L19: ='05_Расходы'!L49 | M19: ='05_Расходы'!M49 | N19: ='05_Расходы'!N49 | O19: ='05_Расходы'!O49 | P19: ='05_Расходы'!P49 | Q19: ='05_Расходы'!Q49 | R19: ='05_Расходы'!R49 | S19: ='05_Расходы'!S49 | ... BY19: ='05_Расходы'!BY49
B20: Клубу: доля паушальных | C20: ₽ | E20: =SUM(L20:W20) | F20: =SUM(X20:AI20) | G20: =SUM(AJ20:AU20) | H20: =SUM(AV20:BG20) | I20: =SUM(BH20:BS20) | J20: =SUM(L20:BS20) | L20: ='05_Расходы'!L47 | M20: ='05_Расходы'!M47 | N20: ='05_Расходы'!N47 | O20: ='05_Расходы'!O47 | P20: ='05_Расходы'!P47 | Q20: ='05_Расходы'!Q47 | R20: ='05_Расходы'!R47 | S20: ='05_Расходы'!S47 | ... BY20: ='05_Расходы'!BY47
B21: Клубу: доля роялти | C21: ₽ | E21: =SUM(L21:W21) | F21: =SUM(X21:AI21) | G21: =SUM(AJ21:AU21) | H21: =SUM(AV21:BG21) | I21: =SUM(BH21:BS21) | J21: =SUM(L21:BS21) | L21: ='05_Расходы'!L48 | M21: ='05_Расходы'!M48 | N21: ='05_Расходы'!N48 | O21: ='05_Расходы'!O48 | P21: ='05_Расходы'!P48 | Q21: ='05_Расходы'!Q48 | R21: ='05_Расходы'!R48 | S21: ='05_Расходы'!S48 | ... BY21: ='05_Расходы'!BY48
B22: Прямые расходы — всего | C22: ₽ | E22: =SUM(L22:W22) | F22: =SUM(X22:AI22) | G22: =SUM(AJ22:AU22) | H22: =SUM(AV22:BG22) | I22: =SUM(BH22:BS22) | J22: =SUM(L22:BS22) | L22: =SUM(L17:L21) | M22: =SUM(M17:M21) | N22: =SUM(N17:N21) | O22: =SUM(O17:O21) | P22: =SUM(P17:P21) | Q22: =SUM(Q17:Q21) | R22: =SUM(R17:R21) | S22: =SUM(S17:S21) | ... BY22: =SUM(BY17:BY21)
B23: Валовая прибыль | C23: ₽ | E23: =SUM(L23:W23) | F23: =SUM(X23:AI23) | G23: =SUM(AJ23:AU23) | H23: =SUM(AV23:BG23) | I23: =SUM(BH23:BS23) | J23: =SUM(L23:BS23) | L23: =L16-L22 | M23: =M16-M22 | N23: =N16-N22 | O23: =O16-O22 | P23: =P16-P22 | Q23: =Q16-Q22 | R23: =R16-R22 | S23: =S16-S22 | ... BY23: =BY16-BY22
B24: ФОТ и кадровые расходы | C24: ₽ | E24: =SUM(L24:W24) | F24: =SUM(X24:AI24) | G24: =SUM(AJ24:AU24) | H24: =SUM(AV24:BG24) | I24: =SUM(BH24:BS24) | J24: =SUM(L24:BS24) | L24: ='05_Расходы'!L30 | M24: ='05_Расходы'!M30 | N24: ='05_Расходы'!N30 | O24: ='05_Расходы'!O30 | P24: ='05_Расходы'!P30 | Q24: ='05_Расходы'!Q30 | R24: ='05_Расходы'!R30 | S24: ='05_Расходы'!S30 | ... BY24: ='05_Расходы'!BY30
B25: ERP | C25: ₽ | E25: =SUM(L25:W25) | F25: =SUM(X25:AI25) | G25: =SUM(AJ25:AU25) | H25: =SUM(AV25:BG25) | I25: =SUM(BH25:BS25) | J25: =SUM(L25:BS25) | L25: ='05_Расходы'!L35 | M25: ='05_Расходы'!M35 | N25: ='05_Расходы'!N35 | O25: ='05_Расходы'!O35 | P25: ='05_Расходы'!P35 | Q25: ='05_Расходы'!Q35 | R25: ='05_Расходы'!R35 | S25: ='05_Расходы'!S35 | ... BY25: ='05_Расходы'!BY35
B26: Офис, аренда, уборка | C26: ₽ | E26: =SUM(L26:W26) | F26: =SUM(X26:AI26) | G26: =SUM(AJ26:AU26) | H26: =SUM(AV26:BG26) | I26: =SUM(BH26:BS26) | J26: =SUM(L26:BS26) | L26: ='05_Расходы'!L36 | M26: ='05_Расходы'!M36 | N26: ='05_Расходы'!N36 | O26: ='05_Расходы'!O36 | P26: ='05_Расходы'!P36 | Q26: ='05_Расходы'!Q36 | R26: ='05_Расходы'!R36 | S26: ='05_Расходы'!S36 | ... BY26: ='05_Расходы'!BY36
B27: Юристы, аудит, бухгалтерия | C27: ₽ | E27: =SUM(L27:W27) | F27: =SUM(X27:AI27) | G27: =SUM(AJ27:AU27) | H27: =SUM(AV27:BG27) | I27: =SUM(BH27:BS27) | J27: =SUM(L27:BS27) | L27: ='05_Расходы'!L37 | M27: ='05_Расходы'!M37 | N27: ='05_Расходы'!N37 | O27: ='05_Расходы'!O37 | P27: ='05_Расходы'!P37 | Q27: ='05_Расходы'!Q37 | R27: ='05_Расходы'!R37 | S27: ='05_Расходы'!S37 | ... BY27: ='05_Расходы'!BY37
B28: Прочие IT | C28: ₽ | E28: =SUM(L28:W28) | F28: =SUM(X28:AI28) | G28: =SUM(AJ28:AU28) | H28: =SUM(AV28:BG28) | I28: =SUM(BH28:BS28) | J28: =SUM(L28:BS28) | L28: ='05_Расходы'!L38 | M28: ='05_Расходы'!M38 | N28: ='05_Расходы'!N38 | O28: ='05_Расходы'!O38 | P28: ='05_Расходы'!P38 | Q28: ='05_Расходы'!Q38 | R28: ='05_Расходы'!R38 | S28: ='05_Расходы'!S38 | ... BY28: ='05_Расходы'!BY38
B29: SMM и подрядчики | C29: ₽ | E29: =SUM(L29:W29) | F29: =SUM(X29:AI29) | G29: =SUM(AJ29:AU29) | H29: =SUM(AV29:BG29) | I29: =SUM(BH29:BS29) | J29: =SUM(L29:BS29) | L29: ='05_Расходы'!L39 | M29: ='05_Расходы'!M39 | N29: ='05_Расходы'!N39 | O29: ='05_Расходы'!O39 | P29: ='05_Расходы'!P39 | Q29: ='05_Расходы'!Q39 | R29: ='05_Расходы'!R39 | S29: ='05_Расходы'!S39 | ... BY29: ='05_Расходы'!BY39
B30: Маркетинг привлечения | C30: ₽ | E30: =SUM(L30:W30) | F30: =SUM(X30:AI30) | G30: =SUM(AJ30:AU30) | H30: =SUM(AV30:BG30) | I30: =SUM(BH30:BS30) | J30: =SUM(L30:BS30) | L30: ='05_Расходы'!L43 | M30: ='05_Расходы'!M43 | N30: ='05_Расходы'!N43 | O30: ='05_Расходы'!O43 | P30: ='05_Расходы'!P43 | Q30: ='05_Расходы'!Q43 | R30: ='05_Расходы'!R43 | S30: ='05_Расходы'!S43 | ... BY30: ='05_Расходы'!BY43
B31: OPEX — прочие (без ФОТ) | C31: ₽ | D31: ERP, офис, юристы, IT, SMM, маркетинг привлечения | E31: =SUM(L31:W31) | F31: =SUM(X31:AI31) | G31: =SUM(AJ31:AU31) | H31: =SUM(AV31:BG31) | I31: =SUM(BH31:BS31) | J31: =SUM(L31:BS31) | L31: =SUM(L25:L30) | M31: =SUM(M25:M30) | N31: =SUM(N25:N30) | O31: =SUM(O25:O30) | P31: =SUM(P25:P30) | Q31: =SUM(Q25:Q30) | R31: =SUM(R25:R30) | S31: =SUM(S25:S30) | ... BY31: =SUM(BY25:BY30)
B32: OPEX — всего | C32: ₽ | D32: ФОТ плюс всё остальное | E32: =SUM(L32:W32) | F32: =SUM(X32:AI32) | G32: =SUM(AJ32:AU32) | H32: =SUM(AV32:BG32) | I32: =SUM(BH32:BS32) | J32: =SUM(L32:BS32) | L32: =L24+L31 | M32: =M24+M31 | N32: =N24+N31 | O32: =O24+O31 | P32: =P24+P31 | Q32: =Q24+Q31 | R32: =R24+R31 | S32: =S24+S31 | ... BY32: =BY24+BY31
B33: EBITDA | C33: ₽ | E33: =SUM(L33:W33) | F33: =SUM(X33:AI33) | G33: =SUM(AJ33:AU33) | H33: =SUM(AV33:BG33) | I33: =SUM(BH33:BS33) | J33: =SUM(L33:BS33) | L33: =L23-L32 | M33: =M23-M32 | N33: =N23-N32 | O33: =O23-O32 | P33: =P23-P32 | Q33: =Q23-Q32 | R33: =R23-R32 | S33: =S23-S32 | ... BY33: =BY23-BY32
B34: EBITDA, % выручки | C34: % | D34: В колонках лет — EBITDA года, делённая на выручку года, а не среднее из помесячных долей | E34: =IF(SUM(L16:W16)=0,0,SUM(L33:W33)/SUM(L16:W16)) | F34: =IF(SUM(X16:AI16)=0,0,SUM(X33:AI33)/SUM(X16:AI16)) | G34: =IF(SUM(AJ16:AU16)=0,0,SUM(AJ33:AU33)/SUM(AJ16:AU16)) | H34: =IF(SUM(AV16:BG16)=0,0,SUM(AV33:BG33)/SUM(AV16:BG16)) | I34: =IF(SUM(BH16:BS16)=0,0,SUM(BH33:BS33)/SUM(BH16:BS16)) | J34: =IF(SUM(L16:BS16)=0,0,SUM(L33:BS33)/SUM(L16:BS16)) | L34: =IF(L16=0,0,L33/L16) | M34: =IF(M16=0,0,M33/M16) | N34: =IF(N16=0,0,N33/N16) | O34: =IF(O16=0,0,O33/O16) | P34: =IF(P16=0,0,P33/P16) | Q34: =IF(Q16=0,0,Q33/Q16) | R34: =IF(R16=0,0,R33/R16) | S34: =IF(S16=0,0,S33/S16) | ... BY34: =IF(BY16=0,0,BY33/BY16)
B35: УСН / минимальный налог | C35: ₽ | E35: =SUM(L35:W35) | F35: =SUM(X35:AI35) | G35: =SUM(AJ35:AU35) | H35: =SUM(AV35:BG35) | I35: =SUM(BH35:BS35) | J35: =SUM(L35:BS35) | L35: ='06_Деньги'!L24 | M35: ='06_Деньги'!M24 | N35: ='06_Деньги'!N24 | O35: ='06_Деньги'!O24 | P35: ='06_Деньги'!P24 | Q35: ='06_Деньги'!Q24 | R35: ='06_Деньги'!R24 | S35: ='06_Деньги'!S24 | ... BY35: ='06_Деньги'!BY24
B36: Прибыль после налога | C36: ₽ | E36: =SUM(L36:W36) | F36: =SUM(X36:AI36) | G36: =SUM(AJ36:AU36) | H36: =SUM(AV36:BG36) | I36: =SUM(BH36:BS36) | J36: =SUM(L36:BS36) | L36: =L33-L35 | M36: =M33-M35 | N36: =N33-N35 | O36: =O33-O35 | P36: =P33-P35 | Q36: =Q33-Q35 | R36: =R33-R35 | S36: =S33-S35 | ... BY36: =BY33-BY35
B38: БДДС — движение денег
B39: Остаток на начало | C39: ₽ | D39: В колонках лет — значение на конец года, в «Итого» — на конец пятого года. Это остаток, а не сумма. | E39: =W39 | F39: =AI39 | G39: =AU39 | H39: =BG39 | I39: =BS39 | J39: =BS39 | L39: =ДеньгиСтарт | M39: =L59 | N39: =M59 | O39: =N59 | P39: =O59 | Q39: =P59 | R39: =Q59 | S39: =R59 | T39: =S59 | ... BY39: =BX59
B40: Поступления: паушальные | C40: ₽ | D40: С НДС, в месяц продажи — она считается после оплаты | E40: =SUM(L40:W40) | F40: =SUM(X40:AI40) | G40: =SUM(AJ40:AU40) | H40: =SUM(AV40:BG40) | I40: =SUM(BH40:BS40) | J40: =SUM(L40:BS40) | L40: ='04_Доходы'!L13 | M40: ='04_Доходы'!M13 | N40: ='04_Доходы'!N13 | O40: ='04_Доходы'!O13 | P40: ='04_Доходы'!P13 | Q40: ='04_Доходы'!Q13 | R40: ='04_Доходы'!R13 | S40: ='04_Доходы'!S13 | ... BY40: ='04_Доходы'!BY13
B41: Поступления: роялти | C41: ₽ | D41: Половина в текущем месяце, половина в следующем | E41: =SUM(L41:W41) | F41: =SUM(X41:AI41) | G41: =SUM(AJ41:AU41) | H41: =SUM(AV41:BG41) | I41: =SUM(BH41:BS41) | J41: =SUM(L41:BS41) | L41: =ДоляПоступлТек*'04_Доходы'!$L103 | M41: =ДоляПоступлТек*'04_Доходы'!M103+(1-ДоляПоступлТек)*'04_Доходы'!L103 | N41: =ДоляПоступлТек*'04_Доходы'!N103+(1-ДоляПоступлТек)*'04_Доходы'!M103 | O41: =ДоляПоступлТек*'04_Доходы'!O103+(1-ДоляПоступлТек)*'04_Доходы'!N103 | P41: =ДоляПоступлТек*'04_Доходы'!P103+(1-ДоляПоступлТек)*'04_Доходы'!O103 | Q41: =ДоляПоступлТек*'04_Доходы'!Q103+(1-ДоляПоступлТек)*'04_Доходы'!P103 | R41: =ДоляПоступлТек*'04_Доходы'!R103+(1-ДоляПоступлТек)*'04_Доходы'!Q103 | S41: =ДоляПоступлТек*'04_Доходы'!S103+(1-ДоляПоступлТек)*'04_Доходы'!R103 | T41: =ДоляПоступлТек*'04_Доходы'!T103+(1-ДоляПоступлТек)*'04_Доходы'!S103 | ... BY41: =ДоляПоступлТек*'04_Доходы'!BY103+(1-ДоляПоступлТек)*'04_Доходы'!BX103
B42: Поступления: мерч | C42: ₽ | D42: С НДС | E42: =SUM(L42:W42) | F42: =SUM(X42:AI42) | G42: =SUM(AJ42:AU42) | H42: =SUM(AV42:BG42) | I42: =SUM(BH42:BS42) | J42: =SUM(L42:BS42) | L42: ='04_Доходы'!L131 | M42: ='04_Доходы'!M131 | N42: ='04_Доходы'!N131 | O42: ='04_Доходы'!O131 | P42: ='04_Доходы'!P131 | Q42: ='04_Доходы'!Q131 | R42: ='04_Доходы'!R131 | S42: ='04_Доходы'!S131 | ... BY42: ='04_Доходы'!BY131
B43: Поступления: лагеря | C43: ₽ | D43: Блок отключён | E43: =SUM(L43:W43) | F43: =SUM(X43:AI43) | G43: =SUM(AJ43:AU43) | H43: =SUM(AV43:BG43) | I43: =SUM(BH43:BS43) | J43: =SUM(L43:BS43) | L43: =0 | M43: =0 | N43: =0 | O43: =0 | P43: =0 | Q43: =0 | R43: =0 | S43: =0 | ... BY43: =0
...

Sheet 03_Сеть
B1: Сеть: продажи, школы и дети
B2: Расшифровка к «Результату». Считается слева направо: план продаж → открытия → когорты школ по месяцам жизни → дети.
B4: Показатель | C4: Ед. | D4: Как считается | E4: Год 1 | F4: Год 2 | G4: Год 3 | H4: Год 4 | I4: Год 5 | J4: Итого 5 лет | L4: М1 | M4: М2 | N4: М3 | O4: М4 | P4: М5 | Q4: М6 | R4: М7 | S4: М8 | T4: М9 | U4: М10 | V4: М11 | W4: М12 | X4: М13 | Y4: М14 | Z4: М15 | AA4: М16 | AB4: М17 | AC4: М18 | AD4: М19 | AE4: М20 | AF4: М21 | AG4: М22 | AH4: М23 | AI4: М24 | AJ4: М25 | AK4: М26 | AL4: М27 | AM4: М28 | AN4: М29 | AO4: М30 | AP4: М31 | AQ4: М32 | AR4: М33 | AS4: М34 | AT4: М35 | AU4: М36 | AV4: М37 | AW4: М38 | AX4: М39 | AY4: М40 | AZ4: М41 | BA4: М42 | BB4: М43 | BC4: М44 | BD4: М45 | BE4: М46 | BF4: М47 | BG4: М48 | BH4: М49 | BI4: М50 | BJ4: М51 | BK4: М52 | BL4: М53 | BM4: М54 | BN4: М55 | BO4: М56 | BP4: М57 | BQ4: М58 | BR4: М59 | BS4: М60 | BT4: тех. 1 | BU4: тех. 2 | BV4: тех. 3 | BW4: тех. 4 | BX4: тех. 5 | BY4: тех. 6
E5: =TEXT(MONTH(DATE(YEAR(СтартМодели),MONTH(СтартМодели)+0,1)),"00")&"."&YEAR(DATE(YEAR(СтартМодели),MONTH(СтартМодели)+0,1))&" – "&TEXT(MONTH(DATE(YEAR(СтартМодели),MONTH(СтартМодели)+11,1)),"00")&"."&YEAR(DATE(YEAR(СтартМодели),MONTH(СтартМодели)+11,1)) | F5: =TEXT(MONTH(DATE(YEAR(СтартМодели),MONTH(СтартМодели)+12,1)),"00")&"."&YEAR(DATE(YEAR(СтартМодели),MONTH(СтартМодели)+12,1))&" – "&TEXT(MONTH(DATE(YEAR(СтартМодели),MONTH(СтартМодели)+23,1)),"00")&"."&YEAR(DATE(YEAR(СтартМодели),MONTH(СтартМодели)+23,1)) | G5: =TEXT(MONTH(DATE(YEAR(СтартМодели),MONTH(СтартМодели)+24,1)),"00")&"."&YEAR(DATE(YEAR(СтартМодели),MONTH(СтартМодели)+24,1))&" – "&TEXT(MONTH(DATE(YEAR(СтартМодели),MONTH(СтартМодели)+35,1)),"00")&"."&YEAR(DATE(YEAR(СтартМодели),MONTH(СтартМодели)+35,1)) | H5: =TEXT(MONTH(DATE(YEAR(СтартМодели),MONTH(СтартМодели)+36,1)),"00")&"."&YEAR(DATE(YEAR(СтартМодели),MONTH(СтартМодели)+36,1))&" – "&TEXT(MONTH(DATE(YEAR(СтартМодели),MONTH(СтартМодели)+47,1)),"00")&"."&YEAR(DATE(YEAR(СтартМодели),MONTH(СтартМодели)+47,1)) | I5: =TEXT(MONTH(DATE(YEAR(СтартМодели),MONTH(СтартМодели)+48,1)),"00")&"."&YEAR(DATE(YEAR(СтартМодели),MONTH(СтартМодели)+48,1))&" – "&TEXT(MONTH(DATE(YEAR(СтартМодели),MONTH(СтартМодели)+59,1)),"00")&"."&YEAR(DATE(YEAR(СтартМодели),MONTH(СтартМодели)+59,1)) | J5: =TEXT(MONTH(DATE(YEAR(СтартМодели),MONTH(СтартМодели)+0,1)),"00")&"."&YEAR(DATE(YEAR(СтартМодели),MONTH(СтартМодели)+0,1))&" – "&TEXT(MONTH(DATE(YEAR(СтартМодели),MONTH(СтартМодели)+59,1)),"00")&"."&YEAR(DATE(YEAR(СтартМодели),MONTH(СтартМодели)+59,1)) | L5: =DATE(YEAR(СтартМодели),MONTH(СтартМодели)+1-1,1) | M5: =DATE(YEAR(СтартМодели),MONTH(СтартМодели)+2-1,1) | N5: =DATE(YEAR(СтартМодели),MONTH(СтартМодели)+3-1,1) | O5: =DATE(YEAR(СтартМодели),MONTH(СтартМодели)+4-1,1) | P5: =DATE(YEAR(СтартМодели),MONTH(СтартМодели)+5-1,1) | Q5: =DATE(YEAR(СтартМодели),MONTH(СтартМодели)+6-1,1) | R5: =DATE(YEAR(СтартМодели),MONTH(СтартМодели)+7-1,1) | S5: =DATE(YEAR(СтартМодели),MONTH(СтартМодели)+8-1,1) | T5: =DATE(YEAR(СтартМодели),MONTH(СтартМодели)+9-1,1) | U5: =DATE(YEAR(СтартМодели),MONTH(СтартМодели)+10-1,1) | V5: =DATE(YEAR(СтартМодели),MONTH(СтартМодели)+11-1,1) | W5: =DATE(YEAR(СтартМодели),MONTH(СтартМодели)+12-1,1) | X5: =DATE(YEAR(СтартМодели),MONTH(СтартМодели)+13-1,1) | Y5: =DATE(YEAR(СтартМодели),MONTH(СтартМодели)+14-1,1) | Z5: =DATE(YEAR(СтартМодели),MONTH(СтартМодели)+15-1,1) | AA5: =DATE(YEAR(СтартМодели),MONTH(СтартМодели)+16-1,1) | AB5: =DATE(YEAR(СтартМодели),MONTH(СтартМодели)+17-1,1) | AC5: =DATE(YEAR(СтартМодели),MONTH(СтартМодели)+18-1,1) | AD5: =DATE(YEAR(СтартМодели),MONTH(СтартМодели)+19-1,1) | AE5: =DATE(YEAR(СтартМодели),MONTH(СтартМодели)+20-1,1) | AF5: =DATE(YEAR(СтартМодели),MONTH(СтартМодели)+21-1,1) | AG5: =DATE(YEAR(СтартМодели),MONTH(СтартМодели)+22-1,1) | AH5: =DATE(YEAR(СтартМодели),MONTH(СтартМодели)+23-1,1) | AI5: =DATE(YEAR(СтартМодели),MONTH(СтартМодели)+24-1,1) | AJ5: =DATE(YEAR(СтартМодели),MONTH(СтартМодели)+25-1,1) | AK5: =DATE(YEAR(СтартМодели),MONTH(СтартМодели)+26-1,1) | AL5: =DATE(YEAR(СтартМодели),MONTH(СтартМодели)+27-1,1) | AM5: =DATE(YEAR(СтартМодели),MONTH(СтартМодели)+28-1,1) | AN5: =DATE(YEAR(СтартМодели),MONTH(СтартМодели)+29-1,1) | AO5: =DATE(YEAR(СтартМодели),MONTH(СтартМодели)+30-1,1) | AP5: =DATE(YEAR(СтартМодели),MONTH(СтартМодели)+31-1,1) | AQ5: =DATE(YEAR(СтартМодели),MONTH(СтартМодели)+32-1,1) | AR5: =DATE(YEAR(СтартМодели),MONTH(СтартМодели)+33-1,1) | AS5: =DATE(YEAR(СтартМодели),MONTH(СтартМодели)+34-1,1) | AT5: =DATE(YEAR(СтартМодели),MONTH(СтартМодели)+35-1,1) | AU5: =DATE(YEAR(СтартМодели),MONTH(СтартМодели)+36-1,1) | AV5: =DATE(YEAR(СтартМодели),MONTH(СтартМодели)+37-1,1) | AW5: =DATE(YEAR(СтартМодели),MONTH(СтартМодели)+38-1,1) | AX5: =DATE(YEAR(СтартМодели),MONTH(СтартМодели)+39-1,1) | AY5: =DATE(YEAR(СтартМодели),MONTH(СтартМодели)+40-1,1) | AZ5: =DATE(YEAR(СтартМодели),MONTH(СтартМодели)+41-1,1) | BA5: =DATE(YEAR(СтартМодели),MONTH(СтартМодели)+42-1,1) | BB5: =DATE(YEAR(СтартМодели),MONTH(СтартМодели)+43-1,1) | BC5: =DATE(YEAR(СтартМодели),MONTH(СтартМодели)+44-1,1) | BD5: =DATE(YEAR(СтартМодели),MONTH(СтартМодели)+45-1,1) | BE5: =DATE(YEAR(СтартМодели),MONTH(СтартМодели)+46-1,1) | BF5: =DATE(YEAR(СтартМодели),MONTH(СтартМодели)+47-1,1) | BG5: =DATE(YEAR(СтартМодели),MONTH(СтартМодели)+48-1,1) | BH5: =DATE(YEAR(СтартМодели),MONTH(СтартМодели)+49-1,1) | BI5: =DATE(YEAR(СтартМодели),MONTH(СтартМодели)+50-1,1) | BJ5: =DATE(YEAR(СтартМодели),MONTH(СтартМодели)+51-1,1) | BK5: =DATE(YEAR(СтартМодели),MONTH(СтартМодели)+52-1,1) | BL5: =DATE(YEAR(СтартМодели),MONTH(СтартМодели)+53-1,1) | BM5: =DATE(YEAR(СтартМодели),MONTH(СтартМодели)+54-1,1) | BN5: =DATE(YEAR(СтартМодели),MONTH(СтартМодели)+55-1,1) | BO5: =DATE(YEAR(СтартМодели),MONTH(СтартМодели)+56-1,1) | BP5: =DATE(YEAR(СтартМодели),MONTH(СтартМодели)+57-1,1) | BQ5: =DATE(YEAR(СтартМодели),MONTH(СтартМодели)+58-1,1) | BR5: =DATE(YEAR(СтартМодели),MONTH(СтартМодели)+59-1,1) | BS5: =DATE(YEAR(СтартМодели),MONTH(СтартМодели)+60-1,1) | BT5: =DATE(YEAR(СтартМодели),MONTH(СтартМодели)+61-1,1) | BU5: =DATE(YEAR(СтартМодели),MONTH(СтартМодели)+62-1,1) | BV5: =DATE(YEAR(СтартМодели),MONTH(СтартМодели)+63-1,1) | BW5: =DATE(YEAR(СтартМодели),MONTH(СтартМодели)+64-1,1) | BX5: =DATE(YEAR(СтартМодели),MONTH(СтартМодели)+65-1,1) | BY5: =DATE(YEAR(СтартМодели),MONTH(СтартМодели)+66-1,1)
B6: Календарь
B7: Месяц | C7: дата | D7: Отсчёт от даты старта на листе вводных Внутренняя механика расчёта: годового итога у этой строки нет, смотрите итоговые строки блока ниже. | L7: =DATE(YEAR(СтартМодели),MONTH(СтартМодели)+1-1,1) | M7: =DATE(YEAR(СтартМодели),MONTH(СтартМодели)+2-1,1) | N7: =DATE(YEAR(СтартМодели),MONTH(СтартМодели)+3-1,1) | O7: =DATE(YEAR(СтартМодели),MONTH(СтартМодели)+4-1,1) | P7: =DATE(YEAR(СтартМодели),MONTH(СтартМодели)+5-1,1) | Q7: =DATE(YEAR(СтартМодели),MONTH(СтартМодели)+6-1,1) | R7: =DATE(YEAR(СтартМодели),MONTH(СтартМодели)+7-1,1) | S7: =DATE(YEAR(СтартМодели),MONTH(СтартМодели)+8-1,1) | T7: =DATE(YEAR(СтартМодели),MONTH(СтартМодели)+9-1,1) | U7: =DATE(YEAR(СтартМодели),MONTH(СтартМодели)+10-1,1) | V7: =DATE(YEAR(СтартМодели),MONTH(СтартМодели)+11-1,1) | W7: =DATE(YEAR(СтартМодели),MONTH(СтартМодели)+12-1,1) | X7: =DATE(YEAR(СтартМодели),MONTH(СтартМодели)+13-1,1) | Y7: =DATE(YEAR(СтартМодели),MONTH(СтартМодели)+14-1,1) | Z7: =DATE(YEAR(СтартМодели),MONTH(СтартМодели)+15-1,1) | AA7: =DATE(YEAR(СтартМодели),MONTH(СтартМодели)+16-1,1) | AB7: =DATE(YEAR(СтартМодели),MONTH(СтартМодели)+17-1,1) | AC7: =DATE(YEAR(СтартМодели),MONTH(СтартМодели)+18-1,1) | AD7: =DATE(YEAR(СтартМодели),MONTH(СтартМодели)+19-1,1) | AE7: =DATE(YEAR(СтартМодели),MONTH(СтартМодели)+20-1,1) | AF7: =DATE(YEAR(СтартМодели),MONTH(СтартМодели)+21-1,1) | AG7: =DATE(YEAR(СтартМодели),MONTH(СтартМодели)+22-1,1) | AH7: =DATE(YEAR(СтартМодели),MONTH(СтартМодели)+23-1,1) | AI7: =DATE(YEAR(СтартМодели),MONTH(СтартМодели)+24-1,1) | AJ7: =DATE(YEAR(СтартМодели),MONTH(СтартМодели)+25-1,1) | AK7: =DATE(YEAR(СтартМодели),MONTH(СтартМодели)+26-1,1) | AL7: =DATE(YEAR(СтартМодели),MONTH(СтартМодели)+27-1,1) | AM7: =DATE(YEAR(СтартМодели),MONTH(СтартМодели)+28-1,1) | AN7: =DATE(YEAR(СтартМодели),MONTH(СтартМодели)+29-1,1) | AO7: =DATE(YEAR(СтартМодели),MONTH(СтартМодели)+30-1,1) | AP7: =DATE(YEAR(СтартМодели),MONTH(СтартМодели)+31-1,1) | AQ7: =DATE(YEAR(СтартМодели),MONTH(СтартМодели)+32-1,1) | AR7: =DATE(YEAR(СтартМодели),MONTH(СтартМодели)+33-1,1) | AS7: =DATE(YEAR(СтартМодели),MONTH(СтартМодели)+34-1,1) | AT7: =DATE(YEAR(СтартМодели),MONTH(СтартМодели)+35-1,1) | AU7: =DATE(YEAR(СтартМодели),MONTH(СтартМодели)+36-1,1) | AV7: =DATE(YEAR(СтартМодели),MONTH(СтартМодели)+37-1,1) | AW7: =DATE(YEAR(СтартМодели),MONTH(СтартМодели)+38-1,1) | AX7: =DATE(YEAR(СтартМодели),MONTH(СтартМодели)+39-1,1) | AY7: =DATE(YEAR(СтартМодели),MONTH(СтартМодели)+40-1,1) | AZ7: =DATE(YEAR(СтартМодели),MONTH(СтартМодели)+41-1,1) | BA7: =DATE(YEAR(СтартМодели),MONTH(СтартМодели)+42-1,1) | BB7: =DATE(YEAR(СтартМодели),MONTH(СтартМодели)+43-1,1) | BC7: =DATE(YEAR(СтартМодели),MONTH(СтартМодели)+44-1,1) | BD7: =DATE(YEAR(СтартМодели),MONTH(СтартМодели)+45-1,1) | BE7: =DATE(YEAR(СтартМодели),MONTH(СтартМодели)+46-1,1) | BF7: =DATE(YEAR(СтартМодели),MONTH(СтартМодели)+47-1,1) | BG7: =DATE(YEAR(СтартМодели),MONTH(СтартМодели)+48-1,1) | BH7: =DATE(YEAR(СтартМодели),MONTH(СтартМодели)+49-1,1) | BI7: =DATE(YEAR(СтартМодели),MONTH(СтартМодели)+50-1,1) | BJ7: =DATE(YEAR(СтартМодели),MONTH(СтартМодели)+51-1,1) | BK7: =DATE(YEAR(СтартМодели),MONTH(СтартМодели)+52-1,1) | BL7: =DATE(YEAR(СтартМодели),MONTH(СтартМодели)+53-1,1) | BM7: =DATE(YEAR(СтартМодели),MONTH(СтартМодели)+54-1,1) | BN7: =DATE(YEAR(СтартМодели),MONTH(СтартМодели)+55-1,1) | BO7: =DATE(YEAR(СтартМодели),MONTH(СтартМодели)+56-1,1) | BP7: =DATE(YEAR(СтартМодели),MONTH(СтартМодели)+57-1,1) | BQ7: =DATE(YEAR(СтартМодели),MONTH(СтартМодели)+58-1,1) | BR7: =DATE(YEAR(СтартМодели),MONTH(СтартМодели)+59-1,1) | BS7: =DATE(YEAR(СтартМодели),MONTH(СтартМодели)+60-1,1) | BT7: =DATE(YEAR(СтартМодели),MONTH(СтартМодели)+61-1,1) | BU7: =DATE(YEAR(СтартМодели),MONTH(СтартМодели)+62-1,1) | BV7: =DATE(YEAR(СтартМодели),MONTH(СтартМодели)+63-1,1) | BW7: =DATE(YEAR(СтартМодели),MONTH(СтартМодели)+64-1,1) | BX7: =DATE(YEAR(СтартМодели),MONTH(СтартМодели)+65-1,1) | BY7: =DATE(YEAR(СтартМодели),MONTH(СтартМодели)+66-1,1)
B8: Год модели (сезон) | C8: № | D8: Сезон длится 12 месяцев от старта Внутренняя механика расчёта: годового итога у этой строки нет, смотрите итоговые строки блока ниже. | L8: =INT((1-1)/12)+1 | M8: =INT((2-1)/12)+1 | N8: =INT((3-1)/12)+1 | O8: =INT((4-1)/12)+1 | P8: =INT((5-1)/12)+1 | Q8: =INT((6-1)/12)+1 | R8: =INT((7-1)/12)+1 | S8: =INT((8-1)/12)+1 | T8: =INT((9-1)/12)+1 | U8: =INT((10-1)/12)+1 | V8: =INT((11-1)/12)+1 | W8: =INT((12-1)/12)+1 | X8: =INT((13-1)/12)+1 | Y8: =INT((14-1)/12)+1 | Z8: =INT((15-1)/12)+1 | AA8: =INT((16-1)/12)+1 | AB8: =INT((17-1)/12)+1 | AC8: =INT((18-1)/12)+1 | AD8: =INT((19-1)/12)+1 | AE8: =INT((20-1)/12)+1 | AF8: =INT((21-1)/12)+1 | AG8: =INT((22-1)/12)+1 | AH8: =INT((23-1)/12)+1 | AI8: =INT((24-1)/12)+1 | AJ8: =INT((25-1)/12)+1 | AK8: =INT((26-1)/12)+1 | AL8: =INT((27-1)/12)+1 | AM8: =INT((28-1)/12)+1 | AN8: =INT((29-1)/12)+1 | AO8: =INT((30-1)/12)+1 | AP8: =INT((31-1)/12)+1 | AQ8: =INT((32-1)/12)+1 | AR8: =INT((33-1)/12)+1 | AS8: =INT((34-1)/12)+1 | AT8: =INT((35-1)/12)+1 | AU8: =INT((36-1)/12)+1 | AV8: =INT((37-1)/12)+1 | AW8: =INT((38-1)/12)+1 | AX8: =INT((39-1)/12)+1 | AY8: =INT((40-1)/12)+1 | AZ8: =INT((41-1)/12)+1 | BA8: =INT((42-1)/12)+1 | BB8: =INT((43-1)/12)+1 | BC8: =INT((44-1)/12)+1 | BD8: =INT((45-1)/12)+1 | BE8: =INT((46-1)/12)+1 | BF8: =INT((47-1)/12)+1 | BG8: =INT((48-1)/12)+1 | BH8: =INT((49-1)/12)+1 | BI8: =INT((50-1)/12)+1 | BJ8: =INT((51-1)/12)+1 | BK8: =INT((52-1)/12)+1 | BL8: =INT((53-1)/12)+1 | BM8: =INT((54-1)/12)+1 | BN8: =INT((55-1)/12)+1 | BO8: =INT((56-1)/12)+1 | BP8: =INT((57-1)/12)+1 | BQ8: =INT((58-1)/12)+1 | BR8: =INT((59-1)/12)+1 | BS8: =INT((60-1)/12)+1 | BT8: =INT((61-1)/12)+1 | BU8: =INT((62-1)/12)+1 | BV8: =INT((63-1)/12)+1 | BW8: =INT((64-1)/12)+1 | BX8: =INT((65-1)/12)+1 | BY8: =INT((66-1)/12)+1
B9: Месяц сезона | C9: № | D9: 1 = первый месяц сезона от даты старта Внутренняя механика расчёта: годового итога у этой строки нет, смотрите итоговые строки блока ниже. | L9: =MOD(1-1,12)+1 | M9: =MOD(2-1,12)+1 | N9: =MOD(3-1,12)+1 | O9: =MOD(4-1,12)+1 | P9: =MOD(5-1,12)+1 | Q9: =MOD(6-1,12)+1 | R9: =MOD(7-1,12)+1 | S9: =MOD(8-1,12)+1 | T9: =MOD(9-1,12)+1 | U9: =MOD(10-1,12)+1 | V9: =MOD(11-1,12)+1 | W9: =MOD(12-1,12)+1 | X9: =MOD(13-1,12)+1 | Y9: =MOD(14-1,12)+1 | Z9: =MOD(15-1,12)+1 | AA9: =MOD(16-1,12)+1 | AB9: =MOD(17-1,12)+1 | AC9: =MOD(18-1,12)+1 | AD9: =MOD(19-1,12)+1 | AE9: =MOD(20-1,12)+1 | AF9: =MOD(21-1,12)+1 | AG9: =MOD(22-1,12)+1 | AH9: =MOD(23-1,12)+1 | AI9: =MOD(24-1,12)+1 | AJ9: =MOD(25-1,12)+1 | AK9: =MOD(26-1,12)+1 | AL9: =MOD(27-1,12)+1 | AM9: =MOD(28-1,12)+1 | AN9: =MOD(29-1,12)+1 | AO9: =MOD(30-1,12)+1 | AP9: =MOD(31-1,12)+1 | AQ9: =MOD(32-1,12)+1 | AR9: =MOD(33-1,12)+1 | AS9: =MOD(34-1,12)+1 | AT9: =MOD(35-1,12)+1 | AU9: =MOD(36-1,12)+1 | AV9: =MOD(37-1,12)+1 | AW9: =MOD(38-1,12)+1 | AX9: =MOD(39-1,12)+1 | AY9: =MOD(40-1,12)+1 | AZ9: =MOD(41-1,12)+1 | BA9: =MOD(42-1,12)+1 | BB9: =MOD(43-1,12)+1 | BC9: =MOD(44-1,12)+1 | BD9: =MOD(45-1,12)+1 | BE9: =MOD(46-1,12)+1 | BF9: =MOD(47-1,12)+1 | BG9: =MOD(48-1,12)+1 | BH9: =MOD(49-1,12)+1 | BI9: =MOD(50-1,12)+1 | BJ9: =MOD(51-1,12)+1 | BK9: =MOD(52-1,12)+1 | BL9: =MOD(53-1,12)+1 | BM9: =MOD(54-1,12)+1 | BN9: =MOD(55-1,12)+1 | BO9: =MOD(56-1,12)+1 | BP9: =MOD(57-1,12)+1 | BQ9: =MOD(58-1,12)+1 | BR9: =MOD(59-1,12)+1 | BS9: =MOD(60-1,12)+1 | BT9: =MOD(61-1,12)+1 | BU9: =MOD(62-1,12)+1 | BV9: =MOD(63-1,12)+1 | BW9: =MOD(64-1,12)+1 | BX9: =MOD(65-1,12)+1 | BY9: =MOD(66-1,12)+1
B10: Сезонность посещаемости | C10: % | D10: Доля детей, посещающих занятия в этом календарном месяце В колонках лет — среднее за год, в «Итого» — среднее за все 60 месяцев. | E10: =AVERAGE(L10:W10) | F10: =AVERAGE(X10:AI10) | G10: =AVERAGE(AJ10:AU10) | H10: =AVERAGE(AV10:BG10) | I10: =AVERAGE(BH10:BS10) | J10: =AVERAGE(L10:BS10) | L10: {=INDEX('01_Вводные'!$B$44:$M$44,1,MONTH(L7))} | M10: {=INDEX('01_Вводные'!$B$44:$M$44,1,MONTH(M7))} | N10: {=INDEX('01_Вводные'!$B$44:$M$44,1,MONTH(N7))} | O10: {=INDEX('01_Вводные'!$B$44:$M$44,1,MONTH(O7))} | P10: {=INDEX('01_Вводные'!$B$44:$M$44,1,MONTH(P7))} | Q10: {=INDEX('01_Вводные'!$B$44:$M$44,1,MONTH(Q7))} | R10: {=INDEX('01_Вводные'!$B$44:$M$44,1,MONTH(R7))} | S10: {=INDEX('01_Вводные'!$B$44:$M$44,1,MONTH(S7))} | ... BY10: {=INDEX('01_Вводные'!$B$44:$M$44,1,MONTH(BY7))}
B12: Продажи франшиз и открытия
